Workbook

Sheet Base_Painel
A1: CodigoMunicipio | B1: Município | C1: Ano-Referência | D1: IQE | E1: IQEF | F1: P | G1: IMEG | H1: IQ2 | I1: IQ5 | J1: IDE2 | K1: IDE5 | L1: DeltaIDEN2 | M1: DeltaIDEN5 | N1: PMNLP2 | O1: PMNMT2 | P1: PMNLP5 | Q1: PMNMT5 | R1: IDALP2 | S1: ABLP2 | T1: BLP2 | U1: PLP2 | V1: AVLP2 | W1: IDAMT2 | X1: ABMT2 | Y1: BMT2 | Z1: PMT2 | AA1: AVMT2 | AB1: IDALP5 | AC1: ABLP5 | AD1: BLP5 | AE1: PLP5 | AF1: AVLP5 | AG1: IDAMT5 | AH1: ABMT5 | AI1: BMT5 | AJ1: PMT5 | AK1: AVMT5 | AL1: TPLP2 | AM1: TPMT2 | AN1: TPLP5 | AO1: TPMT5 | AP1: IVEC | AQ1: IEQLP2 | AR1: ΔDESVFSEtLP2 | AS1: IEQMT2 | AT1: ΔDESVFSEtMT2 | AU1: IEQLP5 | AV1: ΔDESVFSEtLP5 | AW1: IEQMT5 | AX1: ΔDESVFSEtMT5 | AY1: ICMS_Educacional_Estimado
A2: 3200102 | B2: AFONSO CLAUDIO | C2: 2022 | D2: - | E2: - | F2: - | G2: - | H2: - | I2: - | J2: 0.74825865 | K2: 0.6827254 | L2: - | M2: - | N2: 0.60096826 | O2: 0.57938126 | P2: 0.58199833 | Q2: 0.59946105 | R2: 0.8968523 | S2: 0.050847458 | T2: 0.091525424 | U2: 0.40677966 | V2: 0.45084746 | W2: 0.86093972 | X2: 0.03654485 | Y2: 0.17940199 | Z2: 0.40531561 | AA2: 0.37873754 | AB2: 0.74570447 | AC2: 0.089347079 | AD2: 0.28865979 | AE2: 0.35738832 | AF2: 0.26460481 | AG2: 0.68973981 | AH2: 0.12371134 | AI2: 0.32646048 | AJ2: 0.36082474 | AK2: 0.18900344 | AL2: 0.921875 | AM2: 0.93188854 | AN2: 0.89538462 | AO2: 0.89538462 | AP2: - | AQ2: 0.91790376 | AR2: - | AS2: 0.92690307 | AT2: - | AU2: 0.88649627 | AV2: - | AW2: 0.83540873 | AX2: - | AY2: -
A3: 3201159 | B3: BREJETUBA | C3: 2022 | D3: - | E3: - | F3: - | G3: - | H3: - | I3: - | J3: 0.7111989 | K3: 0.65880913 | L3: - | M3: - | N3: 0.55690662 | O3: 0.5389999 | P3: 0.58448261 | Q3: 0.60258826 | R3: 0.83608059 | S3: 0.10897436 | T3: 0.096153846 | U3: 0.42948718 | V3: 0.36538462 | W3: 0.80737327 | X3: 0.04516129 | Y3: 0.25806452 | Z3: 0.49032258 | AA3: 0.20645161 | AB3: 0.71517857 | AC3: 0.10625 | AD3: 0.3125 | AE3: 0.375 | AF3: 0.20625 | AG3: 0.65357143 | AH3: 0.175 | AI3: 0.3 | AJ3: 0.34375 | AK3: 0.18125 | AL3: 0.92307692 | AM3: 0.91715976 | AN3: 0.89385475 | AO3: 0.89385475 | AP3: - | AQ3: 0.93373938 | AR3: - | AS3: 0.87182917 | AT3: - | AU3: 0.86063656 | AV3: - | AW3: 0.80334643 | AX3: - | AY3: -
A4: 3201704 | B4: CONCEICAO DO CASTELO | C4: 2022 | D4: - | E4: - | F4: - | G4: - | H4: - | I4: - | J4: 0.73164138 | K4: 0.67116384 | L4: - | M4: - | N4: 0.55571326 | O4: 0.57266833 | P4: 0.59801013 | Q4: 0.59257901 | R4: 0.85634029 | S4: 0.073033708 | T4: 0.12359551 | U4: 0.46629213 | V4: 0.33707865 | W4: 0.86763519 | X4: 0.06779661 | Y4: 0.11299435 | Z4: 0.48587571 | AA4: 0.33333333 | AB4: 0.73015873 | AC4: 0.086419753 | AD4: 0.32098765 | AE4: 0.38271605 | AF4: 0.20987654 | AG4: 0.63227513 | AH4: 0.14197531 | AI4: 0.39506173 | AJ4: 0.2962963 | AK4: 0.16666667 | AL4: 0.94680851 | AM4: 0.93157895 | AN4: 0.93103448 | AO4: 0.93103448 | AP4: - | AQ4: 0.93683854 | AR4: - | AS4: 0.97416883 | AT4: - | AU4: 0.77095501 | AV4: - | AW4: 0.80216006 | AX4: - | AY4: -
A5: 3201902 | B5: DOMINGOS MARTINS | C5: 2022 | D5: - | E5: - | F5: - | G5: - | H5: - | I5: - | J5: 0.72099132 | K5: 0.67934124 | L5: - | M5: - | N5: 0.56772369 | O5: 0.54786692 | P5: 0.57649123 | Q5: 0.588835 | R5: 0.856469 | S5: 0.051886793 | T5: 0.16037736 | U5: 0.42216981 | V5: 0.36556604 | W5: 0.84439973 | X5: 0.037558685 | Y5: 0.20657277 | Z5: 0.55164319 | AA5: 0.20422535 | AB5: 0.73054306 | AC5: 0.10895884 | AD5: 0.28087167 | AE5: 0.36319613 | AF5: 0.24697337 | AG5: 0.68107921 | AH5: 0.15012107 | AI5: 0.29539952 | AJ5: 0.40435835 | AK5: 0.15012107 | AL5: 0.91182796 | AM5: 0.91416309 | AN5: 0.93650794 | AO5: 0.93650794 | AP5: - | AQ5: 0.9351304 | AR5: - | AS5: 0.96676415 | AT5: - | AU5: 0.79323416 | AV5: - | AW5: 0.81311659 | AX5: - | AY5: -
A6: 3203163 | B6: LARANJA DA TERRA | C6: 2022 | D6: - | E6: - | F6: - | G6: - | H6: - | I6: - | J6: 0.71908685 | K6: 0.73431521 | L6: - | M6: - | N6: 0.53966271 | O6: 0.60130263 | P6: 0.61580712 | Q6: 0.64321047 | R6: 0.79675994 | S6: 0.06185567 | T6: 0.24742268 | U6: 0.37113402 | V6: 0.31958763 | W6: 0.89583333 | X6: 0.020833333 | Y6: 0.14583333 | Z6: 0.41666667 | AA6: 0.41666667 | AB6: 0.82491944 | AC6: 0.037593985 | AD6: 0.2406015 | AE6: 0.37593985 | AF6: 0.34586466 | AG6: 0.74113856 | AH6: 0.14285714 | AI6: 0.20300752 | AJ6: 0.42105263 | AK6: 0.23308271 | AL6: 0.91509434 | AM6: 0.90566038 | AN6: 0.97794118 | AO6: 0.97794118 | AP6: - | AQ6: 0.98162813 | AR6: - | AS6: 0.93954081 | AT6: - | AU6: 0.8412602 | AV6: - | AW6: 0.83099047 | AX6: - | AY6: -
A7: 3204559 | B7: SANTA MARIA DE JETIBA | C7: 2022 | D7: - | E7: - | F7: - | G7: - | H7: - | I7: - | J7: 0.69549616 | K7: 0.69312225 | L7: - | M7: - | N7: 0.52039299 | O7: 0.54486482 | P7: 0.56962657 | Q7: 0.60638514 | R7: 0.77074129 | S7: 0.11340206 | T7: 0.20274914 | U7: 0.39862543 | V7: 0.28522337 | W7: 0.80338983 | X7: 0.047457627 | Y7: 0.26101695 | Z7: 0.38305085 | AA7: 0.30847458 | AB7: 0.77898551 | AC7: 0.047101449 | AD7: 0.30434783 | AE7: 0.4057971 | AF7: 0.24275362 | AG7: 0.7173913 | AH7: 0.094202899 | AI7: 0.32971014 | AJ7: 0.39130435 | AK7: 0.18478261 | AL7: 0.93269231 | AM7: 0.94551282 | AN7: 0.90789474 | AO7: 0.90789474 | AP7: - | AQ7: 0.90413969 | AR7: - | AS7: 0.88035499 | AT7: - | AU7: 0.84891931 | AV7: - | AW7: 0.87910863 | AX7: - | AY7: -
A8: 3205069 | B8: VENDA NOVA DO IMIGRANTE | C8: 2022 | D8: - | E8: - | F8: - | G8: - | H8: - | I8: - | J8: 0.6356028 | K8: 0.66116827 | L8: - | M8: - | N8: 0.5235051 | O8: 0.46452719 | P8: 0.59353826 | Q8: 0.54659175 | R8: 0.78030303 | S8: 0.098484848 | T8: 0.21212121 | U8: 0.39393939 | V8: 0.29545455 | W8: 0.69805195 | X8: 0.098484848 | Y8: 0.35606061 | Z8: 0.46969697 | AA8: 0.075757576 | AB8: 0.75490196 | AC8: 0.088235294 | AD8: 0.2745098 | AE8: 0.32352941 | AF8: 0.31372549 | AG8: 0.57563025 | AH8: 0.24509804 | AI8: 0.31372549 | AJ8: 0.29411765 | AK8: 0.14705882 | AL8: 0.79518072 | AM8: 0.79518072 | AN8: 0.91891892 | AO8: 0.91891892 | AP8: - | AQ8: 0.91869945 | AR8: - | AS8: 0.86189458 | AT8: - | AU8: 0.89585812 | AV8: - | AW8: 0.79437171 | AX8: - | AY8: -
A9: 3200169 | B9: AGUA DOCE DO NORTE | C9: 2022 | D9: - | E9: - | F9: - | G9: - | H9: - | I9: - | J9: 0.62524939 | K9: 0.6709889 | L9: - | M9: - | N9: 0.48144048 | O9: 0.44001546 | P9: 0.54112124 | Q9: 0.56226083 | R9: 0.72216749 | S9: 0.17931034 | T9: 0.17241379 | U9: 0.48275862 | V9: 0.16551724 | W9: 0.62575453 | X9: 0.14084507 | Y9: 0.4084507 | Z9: 0.38028169 | AA9: 0.070422535 | AB9: 0.69340017 | AC9: 0.12280702 | AD9: 0.32163743 | AE9: 0.29239766 | AF9: 0.26315789 | AG9: 0.67418546 | AH9: 0.12865497 | AI9: 0.34502924 | AJ9: 0.39766082 | AK9: 0.12865497 | AL9: 0.89506173 | AM9: 0.87654321 | AN9: 0.93442623 | AO9: 0.93442623 | AP9: - | AQ9: 0.92156326 | AR9: - | AS9: 0.87421364 | AT9: - | AU9: 0.82217351 | AV9: - | AW9: 0.81148686 | AX9: - | AY9: -
A10: 3200136 | B10: AGUIA BRANCA | C10: 2022 | D10: - | E10: - | F10: - | G10: - | H10: - | I10: - | J10: 0.73520252 | K10: 0.68938087 | L10: - | M10: - | N10: 0.55065345 | O10: 0.63731135 | P10: 0.58175715 | Q10: 0.60145127 | R10: 0.83443709 | S10: 0.059602649 | T10: 0.18543046 | U10: 0.47019868 | V10: 0.28476821 | W10: 0.90571429 | X10: 0.033333333 | Y10: 0.10666667 | Z10: 0.32666667 | AA10: 0.53333333 | AB10: 0.75159915 | AC10: 0.1119403 | AD10: 0.23880597 | AE10: 0.44029851 | AF10: 0.20895522 | AG10: 0.69296375 | AH10: 0.11940299 | AI10: 0.32835821 | AJ10: 0.37313433 | AK10: 0.17910448 | AL10: 0.90963855 | AM10: 0.90361446 | AN10: 0.94366197 | AO10: 0.94366197 | AP10: - | AQ10: 0.9487138 | AR10: - | AS10: 0.9275986 | AT10: - | AU10: 0.85650231 | AV10: - | AW10: 0.80262861 | AX10: - | AY10: -
A11: 3200904 | B11: BARRA DE SAO FRANCISCO | C11: 2022 | D11: - | E11: - | F11: - | G11: - | H11: - | I11: - | J11: 0.70381805 | K11: 0.68165564 | L11: - | M11: - | N11: 0.52923382 | O11: 0.54447862 | P11: 0.58475927 | Q11: 0.59127394 | R11: 0.80357143 | S11: 0.099137931 | T11: 0.17025862 | U11: 0.46982759 | V11: 0.26077586 | W11: 0.81650246 | X11: 0.051724138 | Y11: 0.23060345 | Z11: 0.45689655 | AA11: 0.26077586 | AB11: 0.72718894 | AC11: 0.12043011 | AD11: 0.26666667 | AE11: 0.35268817 | AF11: 0.26021505 | AG11: 0.66973886 | AH11: 0.1483871 | AI11: 0.31827957 | AJ11: 0.36344086 | AK11: 0.16989247 | AL11: 0.93737374 | AM11: 0.93360161 | AN11: 0.94704684 | AO11: 0.94704684 | AP11: - | AQ11: 0.90404639 | AR11: - | AS11: 0.9332801 | AT11: - | AU11: 0.8022961 | AV11: - | AW11: 0.85569436 | AX11: - | AY11: -
A12: 3202108 | B12: ECOPORANGA | C12: 2022 | D12: - | E12: - | F12: - | G12: - | H12: - | I12: - | J12: 0.64913312 | K12: 0.62676123 | L12: - | M12: - | N12: 0.49175788 | O12: 0.46100961 | P12: 0.57052822 | Q12: 0.56043936 | R12: 0.7351752 | S12: 0.14622642 | T12: 0.20754717 | U12: 0.46698113 | V12: 0.17924528 | W12: 0.67142857 | X12: 0.1 | Y12: 0.4 | Z12: 0.38571429 | AA12: 0.11428571 | AB12: 0.6592775 | AC12: 0.16666667 | AD12: 0.3045977 | AE12: 0.29310345 | AF12: 0.23563218 | AG12: 0.5444898 | AH12: 0.24 | AI12: 0.37714286 | AJ12: 0.25142857 | AK12: 0.13142857 | AL12: 0.92982456 | AM12: 0.92511013 | AN12: 0.89690722 | AO12: 0.90206186 | AP12: - | AQ12: 0.96547421 | AR12: - | AS12: 0.95086573 | AT12: - | AU12: 0.82064893 | AV12: - | AW12: 0.84721129 | AX12: - | AY12: -
A13: 3203304 | B13: MANTENOPOLIS | C13: 2022 | D13: - | E13: - | F13: - | G13: - | H13: - | I13: - | J13: 0.71994735 | K13: 0.68626777 | L13: - | M13: - | N13: 0.55527388 | O13: 0.59514401 | P13: 0.63596866 | Q13: 0.67259528 | R13: 0.83600583 | S13: 0.096938776 | T13: 0.11734694 | U13: 0.41836735 | V13: 0.36734694 | W13: 0.81958763 | X13: 0.056701031 | Y13: 0.21649485 | Z13: 0.28350515 | AA13: 0.44329897 | AB13: 0.76554622 | AC13: 0.1 | AD13: 0.23529412 | AE13: 0.36470588 | AF13: 0.3 | AG13: 0.73361345 | AH13: 0.088235294 | AI13: 0.31176471 | AJ13: 0.4 | AK13: 0.2 | AL13: 0.91162791 | AM13: 0.90232558 | AN13: 0.85427136 | AO13: 0.85427136 | AP13: - | AQ13: 0.89851486 | AR13: - | AS13: 0.92425143 | AT13: - | AU13: 0.85637419 | AV13: - | AW13: 0.86691978 | AX13: - | AY13: -
... A79: 3205200 | B79: VILA VELHA | C79: 2022 | D79: - | E79: - | F79: - | G79: - | H79: - | I79: - | J79: 0.64547748 | K79: 0.62198228 | L79: - | M79: - | N79: 0.49395491 | O79: 0.49351657 | P79: 0.52984255 | Q79: 0.51760035 | R79: 0.72086419 | S79: 0.15475591 | T79: 0.21766482 | U79: 0.41419225 | V79: 0.21338702 | W79: 0.72255791 | X79: 0.092145015 | Y79: 0.32426989 | Z79: 0.40684794 | AA79: 0.17673716 | AB79: 0.66318546 | AC79: 0.16320143 | AD79: 0.30382294 | AE79: 0.3261793 | AF79: 0.20679633 | AG79: 0.56678931 | AH79: 0.20604703 | AI79: 0.39753639 | AJ79: 0.29697648 | AK79: 0.09944009 | AL79: 0.87244786 | AM79: 0.87335092 | AN79: 0.8761998 | AO79: 0.87463271 | AP79: - | AQ79: 0.89919177 | AR79: - | AS79: 0.92377083 | AT79: - | AU79: 0.82568967 | AV79: - | AW79: 0.86411538 | AX79: - | AY79: -
A80: 3200102 | B80: AFONSO CLAUDIO | C80: 2023 | D80: 0.65481758 | E80: 0.66016135 | F80: 0.982 | G80: 0.30269756 | H80: 0.66540303 | I80: 0.65229881 | J80: 0.7987698 | K80: 0.72941222 | L80: 0.53203627 | M80: 0.5751854 | N80: 0.67640522 | O80: 0.61231358 | P80: 0.58199833 | Q80: 0.59946105 | R80: 0.94360902 | S80: 0.026315789 | T80: 0.052631579 | U80: 0.25 | V80: 0.67105263 | W80: 0.89816124 | X80: 0.02640264 | Y80: 0.1320132 | Z80: 0.37953795 | AA80: 0.4620462 | AB80: 0.817718 | AC80: 0.061688312 | AD80: 0.21103896 | AE80: 0.39285714 | AF80: 0.33441558 | AG80: 0.75927644 | AH80: 0.081168831 | AI80: 0.27922078 | AJ80: 0.38636364 | AK80: 0.25324675 | AL80: 0.96815287 | AM80: 0.96805112 | AN80: 0.94769231 | AO80: 0.94769231 | AP80: 0;302697562312734 | AQ80: 0;915466114531886 | AR80: 1 | AS80: 0;870105037698425 | AT80: 0 | AU80: 0;867293555841263 | AV80: 0 | AW80: 0;870102966048406 | AX80: 0;210790249250935 | AY80: =VLOOKUP(B80,[1]Página1!$A:$E,4,0) -> 7049378
A81: 3201159 | B81: BREJETUBA | C81: 2023 | D81: 0.52865925 | E81: 0.54501322 | F81: 0.981 | G81: 0 | H81: 0.41209987 | I81: 0.74438324 | J81: 0.69728583 | K81: 0.72921619 | L81: 0.12691391 | M81: 0.7595503 | N81: 0.53400564 | O81: 0.53506394 | P81: 0.58448261 | Q81: 0.60258826 | R81: 0.777666 | S81: 0.13380282 | T81: 0.15492958 | U81: 0.38732394 | V81: 0.32394366 | W81: 0.80784708 | X81: 0.035211268 | Y81: 0.27464789 | Z81: 0.44366197 | AA81: 0.24647887 | AB81: 0.82591725 | AC81: 0.049180328 | AD81: 0.21857923 | AE81: 0.35519126 | AF81: 0.37704918 | AG81: 0.7470726 | AH81: 0.087431694 | AI81: 0.28961749 | AJ81: 0.32786885 | AK81: 0.29508197 | AL81: 0.92810458 | AM81: 0.93421053 | AN81: 0.94329897 | AO81: 0.94329897 | AP81: 0 | AQ81: 0;82996622301622 | AR81: 0 | AS81: 0;849300306305591 | AT81: 0 | AU81: 0;826427121276283 | AV81: 0 | AW81: 0;794680665802037 | AX81: 0 | AY81: =VLOOKUP(B81,[1]Página1!$A:$E,4,0) -> 5691232.2
A82: 3201704 | B82: CONCEICAO DO CASTELO | C82: 2023 | D82: 0.65894721 | E82: 0.64153731 | F82: 0.987 | G82: 0.41214061 | H82: 0.58443743 | I82: 0.72718714 | J82: 0.7622147 | K82: 0.73624208 | L82: 0.40666016 | M82: 0.7181322 | N82: 0.60254714 | O82: 0.59285256 | P82: 0.59801013 | Q82: 0.59257901 | R82: 0.87510693 | S82: 0.083832335 | T82: 0.071856287 | U82: 0.34131737 | V82: 0.50299401 | W82: 0.88898451 | X82: 0.018072289 | Y82: 0.1626506 | Z82: 0.42771084 | AA82: 0.39156627 | AB82: 0.83166023 | AC82: 0.032432432 | AD82: 0.23783784 | AE82: 0.36756757 | AF82: 0.36216216 | AG82: 0.72972973 | AH82: 0.097297297 | AI82: 0.3027027 | AJ82: 0.33513514 | AK82: 0.26486486 | AL82: 0.97093023 | AM82: 0.97076023 | AN82: 0.97368421 | AO82: 0.97368421 | AP82: 0;412140612167181 | AQ82: 0;894852272817815 | AR82: 0 | AS82: 0;927046732518117 | AT82: 1 | AU82: 0;867143029578016 | AV82: 0;419952504643223 | AW82: 0;847388234266154 | AX82: 0;228609944025502 | AY82: =VLOOKUP(B82,[1]Página1!$A:$E,4,0) -> 7346675
A83: 3201902 | B83: DOMINGOS MARTINS | C83: 2023 | D83: 0.67443002 | E83: 0.61734279 | F83: 0.984 | G83: 0.63126715 | H83: 0.61119755 | I83: 0.62656064 | J83: 0.76036914 | K83: 0.72054589 | L83: 0.46202596 | M83: 0.53257539 | N83: 0.63150015 | O83: 0.56585427 | P83: 0.57649123 | Q83: 0.588835 | R83: 0.88773186 | S83: 0.079726651 | T83: 0.056947608 | U83: 0.27562642 | V83: 0.58769932 | W83: 0.85091743 | X83: 0.038990826 | Y83: 0.19266055 | Z83: 0.48165138 | AA83: 0.28669725 | AB83: 0.82302212 | AC83: 0.052493438 | AD83: 0.21784777 | AE83: 0.43307087 | AF83: 0.29658793 | AG83: 0.75215598 | AH83: 0.1023622 | AI83: 0.25459318 | AJ83: 0.38582677 | AK83: 0.25721785 | AL83: 0.96061269 | AM83: 0.95404814 | AN83: 0.92926829 | AO83: 0.92926829 | AP83: 0;631267146038531 | AQ83: 0;938473936690301 | AR83: 1 | AS83: 0;944249065845649 | AT83: 1 | AU83: 0;834081288515759 | AV83: 0;197552582303288 | AW83: 0;874323896164553 | AX83: 0;327516001850836 | AY83: =VLOOKUP(B83,[1]Página1!$A:$E,4,0) -> 7260514
A84: 3203163 | B84: LARANJA DA TERRA | C84: 2023 | D84: 0.7847686 | E84: 0.70024086 | F84: 0.964 | G84: 1 | H84: 0.75605429 | I84: 0.61652071 | J84: 0.79847617 | K84: 0.76696426 | L84: 0.71363241 | M84: 0.46607717 | N84: 0.64475286 | O84: 0.66260882 | P84: 0.61580712 | Q84: 0.64321047 | R84: 0.93386243 | S84: 0.018518519 | T84: 0.083333333 | U84: 0.33333333 | V84: 0.56481481 | W84: 0.93915344 | X84: 0.018518519 | Y84: 0.074074074 | Z84: 0.30555556 | AA84: 0.60185185 | AB84: 0.88888889 | AC84: 0.037037037 | AD84: 0.12962963 | AE84: 0.41666667 | AF84: 0.41666667 | AG84: 0.8505291 | AH84: 0.027777778 | AI84: 0.21296296 | AJ84: 0.42592593 | AK84: 0.33333333 | AL84: 0.94736842 | AM84: 0.96428571 | AN84: 0.93913043 | AO84: 0.93913043 | AP84: 1 | AQ84: 0;965892835967916 | AR84: 1 | AS84: 0;966583080639562 | AT84: 1 | AU84: 0;935589929246345 | AV84: 1 | AW84: 0;919346944273312 | AX84: 1 | AY84: =VLOOKUP(B84,[1]Página1!$A:$E,4,0) -> 8448353.7
A85: 3204559 | B85: SANTA MARIA DE JETIBA | C85: 2023 | D85: 0.75970067 | E85: 0.70632088 | F85: 0.964 | G85: 0.80450706 | H85: 0.75924894 | I85: 0.6269288 | J85: 0.77899888 | K85: 0.7328399 | L85: 0.73949899 | M85: 0.52101769 | N85: 0.63594719 | O85: 0.63228349 | P85: 0.56962657 | Q85: 0.60638514 | R85: 0.89297348 | S85: 0.058631922 | T85: 0.084690554 | U85: 0.27035831 | V85: 0.58631922 | W85: 0.93531875 | X85: 0.016286645 | Y85: 0.084690554 | Z85: 0.4267101 | AA85: 0.4723127 | AB85: 0.82512315 | AC85: 0.044827586 | AD85: 0.22758621 | AE85: 0.45172414 | AF85: 0.27586207 | AG85: 0.79014778 | AH85: 0.075862069 | AI85: 0.23448276 | AJ85: 0.43448276 | AK85: 0.25517241 | AL85: 0.93597561 | AM85: 0.93883792 | AN85: 0.94771242 | AO85: 0.94771242 | AP85: 0;804507058685125 | AQ85: 0;973264939881325 | AR85: 1 | AS85: 0;983467876684951 | AT85: 1 | AU85: 0;881859165817393 | AV85: 0;218028234740498 | AW85: 0;923342131941175 | AX85: 1 | AY85: =VLOOKUP(B85,[1]Página1!$A:$E,4,0) -> 8178487.3
A86: 3205069 | B86: VENDA NOVA DO IMIGRANTE | C86: 2023 | D86: 0.76201751 | E86: 0.71531073 | F86: 0.992 | G86: 0.75 | H86: 0.77670591 | I86: 0.62321796 | J86: 0.73211357 | K86: 0.70368243 | L86: 0.82129825 | M86: 0.54275349 | N86: 0.61069636 | O86: 0.5440348 | P86: 0.59353826 | Q86: 0.54659175 | R86: 0.90934066 | S86: 0.057692308 | T86: 0.057692308 | U86: 0.36538462 | V86: 0.51923077 | W86: 0.84313725 | X86: 0.039215686 | Y86: 0.20588235 | Z86: 0.5 | AA86: 0.25490196 | AB86: 0.8494898 | AC86: 0.017857143 | AD86: 0.23214286 | AE86: 0.40178571 | AF86: 0.34821429 | AG86: 0.67857143 | AH86: 0.10714286 | AI86: 0.375 | AJ86: 0.36607143 | AK86: 0.15178571 | AL86: 0.88135593 | AM86: 0.87179487 | AN86: 0.91056911 | AO86: 0.91056911 | AP86: 0;75 | AQ86: 0;906034696117175 | AR86: 1 | AS86: 0;974077977520727 | AT86: 1 | AU86: 0;860728195093036 | AV86: 0 | AW86: 0;921979568787364 | AX86: 1 | AY86: =VLOOKUP(B86,[1]Página1!$A:$E,4,0) -> 8203429
A87: 3200169 | B87: AGUA DOCE DO NORTE | C87: 2023 | D87: 0.70239656 | E87: 0.73192125 | F87: 0.996 | G87: 0.27101123 | H87: 0.87508902 | I87: 0.51716959 | J87: 0.75017805 | K87: 0.68820605 | L87: 1 | M87: 0.34613314 | N87: 0.59583351 | O87: 0.63164712 | P87: 0.54112124 | Q87: 0.56226083 | R87: 0.85966387 | S87: 0.076470588 | T87: 0.11176471 | U87: 0.35882353 | V87: 0.45294118 | W87: 0.90617075 | X87: 0.029585799 | Y87: 0.11242604 | Z87: 0.23668639 | AA87: 0.62130178 | AB87: 0.73239437 | AC87: 0.070422535 | AD87: 0.34507042 | AE87: 0.34507042 | AF87: 0.23943662 | AG87: 0.722334 | AH87: 0.11267606 | AI87: 0.28873239 | AJ87: 0.38732394 | AK87: 0.21126761 | AL87: 0.90425532 | AM87: 0.89893617 | AN87: 0.92207792 | AO87: 0.92207792 | AP87: 0;271011229719311 | AQ87: 0;890953634480972 | AR87: 0 | AS87: 0;958855983411389 | AT87: 1 | AU87: 0;818989047487225 | AV87: 0 | AW87: 0;827330435385467 | AX87: 0;0840449188772421 | AY87: =VLOOKUP(B87,[1]Página1!$A:$E,4,0) -> 7561585.1
A88: 3200136 | B88: AGUIA BRANCA | C88: 2023 | D88: 0.77040001 | E88: 0.71596432 | F88: 1 | G88: 0.79483324 | H88: 0.7701334 | I88: 0.63471071 | J88: 0.81624414 | K88: 0.73129917 | L88: 0.72402267 | M88: 0.53812224 | N88: 0.66010967 | O88: 0.70193514 | P88: 0.58175715 | Q88: 0.60145127 | R88: 0.96903097 | S88: 0.006993007 | T88: 0.041958042 | U88: 0.34265734 | V88: 0.60839161 | W88: 0.97973658 | X88: 0 | Y88: 0.035460993 | Z88: 0.19148936 | AA88: 0.77304965 | AB88: 0.82817183 | AC88: 0.027972028 | AD88: 0.25174825 | AE88: 0.3986014 | AF88: 0.32167832 | AG88: 0.77422577 | AH88: 0.06993007 | AI88: 0.27272727 | AJ88: 0.41258741 | AK88: 0.24475524 | AL88: 0.94078947 | AM88: 0.93377483 | AN88: 0.94078947 | AO88: 0.94078947 | AP88: 0;794833236703196 | AQ88: 0;92442415944975 | AR88: 1 | AS88: 0;954959181980849 | AT88: 1 | AU88: 0;945758148761604 | AV88: 1 | AW88: 0;838023799880123 | AX88: 0;179332946812785 | AY88: =VLOOKUP(B88,[1]Página1!$A:$E,4,0) -> 8293670
A89: 3200904 | B89: BARRA DE SAO FRANCISCO | C89: 2023 | D89: 0.69046041 | E89: 0.64321726 | F89: 0.98 | G89: 0.62138886 | H89: 0.64541112 | I89: 0.63992646 | J89: 0.75494069 | K89: 0.72564368 | L89: 0.53588155 | M89: 0.55420924 | N89: 0.59762988 | O89: 0.60698724 | P89: 0.58475927 | Q89: 0.59127394 | R89: 0.87963774 | S89: 0.065439673 | T89: 0.096114519 | U89: 0.37627812 | V89: 0.46216769 | W89: 0.88765034 | X89: 0.034907597 | Y89: 0.13552361 | Z89: 0.37577002 | AA89: 0.45379877 | AB89: 0.827654 | AC89: 0.050458716 | AD89: 0.21330275 | AE89: 0.37614679 | AF89: 0.36009174 | AG89: 0.75819135 | AH89: 0.096330275 | AI89: 0.25458716 | AJ89: 0.42201835 | AK89: 0.22706422 | AL89: 0.93499044 | AM89: 0.93295019 | AN89: 0.93361884 | AO89: 0.93361884 | AP89: 0;621388863197248 | AQ89: 0;905584951039975 | AR89: 1 | AS89: 0;974207133937739 | AT89: 1 | AU89: 0;852205393657482 | AV89: 0;252444672503853 | AW89: 0;889333559201718 | AX89: 0;233110780285138 | AY89: =VLOOKUP(B89,[1]Página1!$A:$E,4,0) -> 7433087.6
A90: 3202108 | B90: ECOPORANGA | C90: 2023 | D90: 0.70197158 | E90: 0.71359327 | F90: 1 | G90: 0.34970859 | H90: 0.69366431 | I90: 0.74348672 | J90: 0.72099999 | K90: 0.70061713 | L90: 0.66632862 | M90: 0.7863563 | N90: 0.57189115 | O90: 0.55173472 | P90: 0.57052822 | Q90: 0.56043936 | R90: 0.82392027 | S90: 0.1255814 | T90: 0.088372093 | U90: 0.37209302 | V90: 0.41395349 | W90: 0.82843792 | X90: 0.070093458 | Y90: 0.17757009 | Z90: 0.49065421 | AA90: 0.26168224 | AB90: 0.76874116 | AC90: 0.084158416 | AD90: 0.25742574 | AE90: 0.31683168 | AF90: 0.34158416 | AG90: 0.69519095 | AH90: 0.12376238 | AI90: 0.31683168 | AJ90: 0.37128713 | AK90: 0.18811881 | AL90: 0.93073593 | AM90: 0.93043478 | AN90: 0.93953488 | AO90: 0.93953488 | AP90: 0;34970859058683 | AQ90: 0;871194038355809 | AR90: 0 | AS90: 0;907119177382218 | AT90: 1 | AU90: 0;859641488331641 | AV90: 0;217409126173709 | AW90: 0;874931021387557 | AX90: 0;18142523617361 | AY90: =VLOOKUP(B90,[1]Página1!$A:$E,4,0) -> 7557010
A91: 3203304 | B91: MANTENOPOLIS | C91: 2023 | D91: 0.81334068 | E91: 0.83843172 | F91: 0.999 | G91: 0.51058985 | H91: 0.82508609 | I91: 0.85845015 | J91: 0.81816163 | K91: 0.77955039 | L91: 0.83201055 | M91: 0.93734992 | N91: 0.69841245 | O91: 0.669675 | P91: 0.63596866 | Q91: 0.67259528 | R91: 0.96497696 | S91: 0.012903226 | T91: 0.038709677 | U91: 0.21935484 | V91: 0.72903226 | W91: 0.94360902 | X91: 0 | Y91: 0.09868421 | Z91: 0.28947368 | AA91: 0.61184211 | AB91: 0.87554777 | AC91: 0.036809816 | AD91: 0.15337423 | AE91: 0.26993865 | AF91: 0.5398773 | AG91: 0.84837862 | AH91: 0.042944785 | AI91: 0.19018405 | AJ91: 0.33742331 | AK91: 0.42944785 | AL91: 0.94512195 | AM91: 0.9382716 | AN91: 0.94767442 | AO91: 0.94767442 | AP91: 0;510589847571799 | AQ91: 0;945168858904682 | AR91: 1 | AS91: 0;96078770598494 | AT91: 1 | AU91: 0;862458089513558 | AV91: 0;0423593902871938 | AW91: 0;852109496770223 | AX91: 0 | AY91: =VLOOKUP(B91,[1]Página1!$A:$E,4,0) -> 8755943.8
A92: 3200706 | B92: ATILIO VIVACQUA | C92: 2023 | D92: 0.83544468 | E92: 0.76834954 | F92: 0.984 | G92: 1 | H92: 0.8328749 | I92: 0.67156151 | J92: 0.77875748 | K92: 0.74245631 | L92: 0.88699231 | M92: 0.60066671 | N92: 0.61046441 | O92: 0.68340947 | P92: 0.58261752 | Q92: 0.61731899 | R92: 0.87060041 | S92: 0.050724638 | T92: 0.13768116 | U92: 0.33333333 | V92: 0.47826087 | W92: 0.95238095 | X92: 0.014492754 | Y92: 0.057971015 | Z92: 0.3115942 | AA92: 0.61594203 | AB92: 0.83697479 | AC92: 0.058823529 | AD92: 0.18235294 | AE92: 0.42352941 | AF92: 0.33529412 | AG92: 0.80336134 | AH92: 0.058823529 | AI92: 0.24117647 | AJ92: 0.4 | AK92: 0.3 | AL92: 0.93243243 | AM92: 0.93243243 | AN92: 0.94972067 | AO92: 0.94972067 | AP92: 1 | AQ92: 0;97030787695555 | AR92: 1 | AS92: 0;987600790820958 | AT92: 1 | AU92: 0;90828050762713 | AV92: 1 | AW92: 0;926997859385594 | AX92: 1 | AY92: =VLOOKUP(B92,[1]Página1!$A:$E,4,0) -> 8993902.3
A93: 3201209 | B93: CACHOEIRO DE ITAPEMIRIM | C93: 2023 | D93: 0.7015498 | E93: 0.68106457 | F93: 0.95 | G93: 0.54869734 | H93: 0.69992523 | I93: 0.65277357 | J93: 0.69042461 | K93: 0.66718076 | L93: 0.70942586 | M93: 0.63836639 | N93: 0.5461612 | O93: 0.52402403 | P93: 0.53992351 | Q93: 0.53068096 | R93: 0.78397213 | S93: 0.12973534 | T93: 0.15101194 | U93: 0.35288012 | V93: 0.3663726 | W93: 0.7798328 | X93: 0.080787157 | Y93: 0.24391507 | Z93: 0.44691869 | AA93: 0.22837908 | AB93: 0.73591441 | AC93: 0.10614224 | AD93: 0.27640086 | AE93: 0.3518319 | AF93: 0.265625 | AG93: 0.63453537 | AH93: 0.15803668 | AI93: 0.36299892 | AJ93: 0.32632147 | AK93: 0.15264293 | AL93: 0.90299906 | AM93: 0.90742481 | AN93: 0.91338583 | AO93: 0.91240157 | AP93: 0;548697344381977 | AQ93: 0;904934149515312 | AR93: 1 | AS93: 0;940358508240233 | AT93: 1 | AU93: 0;836867363769457 | AV93: 0;194789377527908 | AW93: 0;840047147801459 | AX93: 0 | AY93: =VLOOKUP(B93,[1]Página1!$A:$E,4,0) -> 7552469.4
A94: 3201407 | B94: CASTELO | C94: 2023 | D94: 0.6851908 | E94: 0.5904247 | F94: 0.96 | G94: 0.85262338 | H94: 0.56613517 | I94: 0.62685901 | J94: 0.72942975 | K94: 0.69375129 | L94: 0.40284058 | M94: 0.55996673 | N94: 0.59277989 | O94: 0.56411116 | P94: 0.55549469 | Q94: 0.56126313 | R94: 0.85525321 | S94: 0.087301587 | T94: 0.1005291 | U94: 0.33597884 | V94: 0.47619048 | W94: 0.86407393 | X94: 0.040431267 | Y94: 0.1671159 | Z94: 0.50673854 | AA94: 0.28571429 | AB94: 0.7775 | AC94: 0.0925 | AD94: 0.2275 | AE94: 0.405 | AF94: 0.275 | AG94: 0.68714286 | AH94: 0.11 | AI94: 0.355 | AJ94: 0.35 | AK94: 0.185 | AL94: 0.90214797 | AM94: 0.88755981 | AN94: 0.92592593 | AO94: 0.92592593 | AP94: 0;852623383961529 | AQ94: 0;92792555406979 | AR94: 1 | AS94: 0;951756857529633 | AT94: 1 | AU94: 0;862497600179922 | AV94: 0;410493535846117 | AW94: 0;932269441425863 | AX94: 1 | AY94: =VLOOKUP(B94,[1]Página1!$A:$E,4,0) -> 7376358.1
A95: 3202603 | B95: ICONHA | C95: 2023 | D95: 0.58748054 | E95: 0.51302231 | F95: 0.993 | G95: 0.52943283 | H95: 0.50360486 | I95: 0.52714849 | J95: 0.70708486 | K95: 0.72950075 | L95: 0.30012487 | M95: 0.32479622 | N95: 0.58232278 | O95: 0.54205675 | P95: 0.59881454 | Q95: 0.57824734 | R95: 0.84769776 | S95: 0.090909091 | T95: 0.10743802 | U95: 0.36363636 | V95: 0.43801653 | W95: 0.82196162 | X95: 0.037313433 | Y95: 0.24626866 | Z95: 0.48507463 | AA95: 0.23134328 | AB95: 0.85518591 | AC95: 0.02739726 | AD95: 0.20547945 | AE95: 0.38356164 | AF95: 0.38356164 | AG95: 0.71819961 | AH95: 0.082191781 | AI95: 0.34931507 | AJ95: 0.34931507 | AK95: 0.21917808 | AL95: 0.82312925 | AM95: 0.91156463 | AN95: 0.95424837 | AO95: 0.95424837 | AP95: 0;529432825207955 | AQ95: 0;991987919573857 | AR95: 1 | AS95: 0;967488482933076 | AT95: 1 | AU95: 0;809003450136238 | AV95: 0 | AW95: 0;839327998608791 | AX95: 0;117731300831821 | AY95: =VLOOKUP(B95,[1]Página1!$A:$E,4,0) -> 6324467.4
A96: 3202801 | B96: ITAPEMIRIM | C96: 2023 | D96: 0.6536045 | E96: 0.68214929 | F96: 0.924 | G96: 0.25 | H96: 0.67196932 | I96: 0.69741924 | J96: 0.69569551 | K96: 0.67237246 | L96: 0.64824314 | M96: 0.72246601 | N96: 0.53798261 | O96: 0.55687032 | P96: 0.54032346 | Q96: 0.53391073 | R96: 0.7532028 | S96: 0.13367174 | T96: 0.19796954 | U96: 0.31641286 | V96: 0.35194585 | W96: 0.81509712 | X96: 0.061962134 | Y96: 0.2151463 | Z96: 0.42340792 | AA96: 0.29948365 | AB96: 0.74577573 | AC96: 0.11290323 | AD96: 0.24731183 | AE96: 0.37096774 | AF96: 0.2688172 | AG96: 0.64618536 | AH96: 0.14695341 | AI96: 0.36200717 | AJ96: 0.34946237 | AK96: 0.14157706 | AL96: 0.91770186 | AM96: 0.9078125 | AN96: 0.91927512 | AO96: 0.91927512 | AP96: 0;25 | AQ96: 0;851981747011823 | AR96: 0 | AS96: 0;922279063875751 | AT96: 1 | AU96: 0;826433007650066 | AV96: 0 | AW96: 0;848687844802876 | AX96: 0 | AY96: =VLOOKUP(B96,[1]Página1!$A:$E,4,0) -> 7036318.8
A97: 3203106 | B97: JERONIMO MONTEIRO | C97: 2023 | D97: 0.50822669 | E97: 0.46246671 | F97: 0.98 | G97: 0.25 | H97: 0.4627939 | I97: 0.46197591 | J97: 0.70397421 | K97: 0.69180857 | L97: 0.2216136 | M97: 0.23214325 | N97: 0.5643303 | O97: 0.51281261 | P97: 0.53944623 | Q97: 0.54330032 | R97: 0.79036348 | S97: 0.14201183 | T97: 0.1183432 | U97: 0.30177515 | V97: 0.43786982 | W97: 0.77587682 | X97: 0.083832335 | Y97: 0.24550898 | Z97: 0.49101796 | AA97: 0.17964072 | AB97: 0.73593074 | AC97: 0.12121212 | AD97: 0.25 | AE97: 0.34848485 | AF97: 0.28030303 | AG97: 0.67748918 | AH97: 0.13636364 | AI97: 0.32575758 | AJ97: 0.39393939 | AK97: 0.14393939 | AL97: 0.94413408 | AM97: 0.94350282 | AN97: 0.97777778 | AO97: 0.97777778 | AP97: 0;25 | AQ97: 0;866690833549074 | AR97: 0 | AS97: 0;911271392842587 | AT97: 1 | AU97: 0;842618881348393 | AV97: 0 | AW97: 0;858369065231151 | AX97: 0 | AY97: =VLOOKUP(B97,[1]Página1!$A:$E,4,0) -> 5471267.4
A98: 3203320 | B98: MARATAIZES | C98: 2023 | D98: 0.80360601 | E98: 0.73036572 | F98: 0.949 | G98: 1 | H98: 0.77454543 | I98: 0.66409617 | J98: 0.71414646 | K98: 0.68659303 | L98: 0.8349444 | M98: 0.64159931 | N98: 0.57310774 | O98: 0.53228633 | P98: 0.55632452 | Q98: 0.55116102 | R98: 0.85527544 | S98: 0.08496732 | T98: 0.10457516 | U98: 0.42156863 | V98: 0.38888889 | W98: 0.8145404 | X98: 0.04376013 | Y98: 0.24797407 | Z98: 0.49432739 | AA98: 0.21393841 | AB98: 0.78100471 | AC98: 0.078754579 | AD98: 0.24542125 | AE98: 0.38278388 | AF98: 0.29304029 | AG98: 0.69511555 | AH98: 0.10110294 | AI98: 0.35661765 | AJ98: 0.39154412 | AK98: 0.15073529 | AL98: 0.8973607 | AM98: 0.91407407 | AN98: 0.90247934 | AO98: 0.89917355 | AP98: 1 | AQ98: 0;946129512081496 | AR98: 1 | AS98: 0;951472063709399 | AT98: 1 | AU98: 0;92328294935666 | AV98: 1 | AW98: 0;927445642633976 | AX98: 1 | AY98: =VLOOKUP(B98,[1]Página1!$A:$E,4,0) -> 8651146.1
A99: 3203403 | B99: MIMOSO DO SUL | C99: 2023 | D99: 0.70675518 | E99: 0.73978721 | F99: 0.971 | G99: 0.28836088 | H99: 0.71707448 | I99: 0.7738563 | J99: 0.72318354 | K99: 0.68874775 | L99: 0.71096542 | M99: 0.85896486 | N99: 0.57975928 | O99: 0.57778517 | P99: 0.56826813 | Q99: 0.54507309 | R99: 0.82433115 | S99: 0.088339223 | T99: 0.13427562 | U99: 0.35335689 | V99: 0.41342756 | W99: 0.83400402 | X99: 0.066901408 | Y99: 0.15492958 | Z99: 0.38028169 | AA99: 0.38732394 | AB99: 0.772842 | AC99: 0.077738516 | AD99: 0.2614841 | AE99: 0.3180212 | AF99: 0.34275618 | AG99: 0.65471984 | AH99: 0.16961131 | AI99: 0.30742049 | AJ99: 0.37102473 | AK99: 0.15194346 | AL99: 0.90415335 | AM99: 0.91025641 | AN99: 0.92786885 | AO99: 0.92786885 | AP99: 0;288360883263719 | AQ99: 0;884997599363395 | AR99: 0 | AS99: 0;992876509006904 | AT99: 1 | AU99: 0;83932177587726 | AV99: 0;0570546149371454 | AW99: 0;874294430042654 | AX99: 0;0963889181177286 | AY99: =VLOOKUP(B99,[1]Página1!$A:$E,4,0) -> 7608507.4
A100: 3203809 | B100: MUQUI | C100: 2023 | D100: 0.74282038 | E100: 0.68118992 | F100: 0.96 | G100: 0.8132496 | H100: 0.70712038 | I100: 0.64229423 | J100: 0.7173472 | K100: 0.70345094 | L100: 0.69689356 | M100: 0.58113752 | N100: 0.54510499 | O100: 0.54742039 | P100: 0.55067217 | Q100: 0.56005229 | R100: 0.78195489 | S100: 0.10526316 | T100: 0.19736842 | U100: 0.33552632 | V100: 0.36184211 | W100: 0.84755513 | X100: 0.033557047 | Y100: 0.20805369 | Z100: 0.53691275 | AA100: 0.22147651 | AB100: 0.76190476 | AC100: 0.094339623 | AD100: 0.25157233 | AE100: 0.37106918 | AF100: 0.28301887 | AG100: 0.71698113 | AH100: 0.10691824 | AI100: 0.3081761 | AJ100: 0.40251572 | AK100: 0.18238994 | AL100: 0.97435897 | AM100: 0.96129032 | AN100: 0.96363636 | AO100: 0.96363636 | AP100: 0;813249599941053 | AQ100: 0;924949929411012 | AR100: 1 | AS100: 0;995612032810895 | AT100: 1 | AU100: 0;90606004306284 | AV100: 1 | AW100: 0;877194117031292 | AX100: 0;252998399764211 | AY100: =VLOOKUP(B100,[1]Página1!$A:$E,4,0) -> 7996764.1
A101: 3204302 | B101: PRESIDENTE KENNEDY | C101: 2023 | D101: 0.7022628 | E101: 0.67879909 | F101: 0.948 | G101: 0.56602293 | H101: 0.67243863 | I101: 0.68833978 | J101: 0.70254433 | K101: 0.68240597 | L101: 0.64233293 | M101: 0.69427358 | N101: 0.54550573 | O101: 0.5363714 | P101: 0.54103148 | Q101: 0.52800893 | R101: 0.80501016 | S101: 0.09478673 | T101: 0.17535545 | U101: 0.40758294 | V101: 0.32227488 | W101: 0.78777473 | X101: 0.052884615 | Y101: 0.27884615 | Z101: 0.375 | AA101: 0.29326923 | AB101: 0.7742413 | AC101: 0.056994819 | AD101: 0.29533679 | AE101: 0.43523316 | AF101: 0.21243523 | AG101: 0.64544782 | AH101: 0.10880829 | AI101: 0.43005181 | AJ101: 0.3626943 | AK101: 0.098445596 | AL101: 0.9254386 | AM101: 0.93273543 | AN101: 0.95073892 | AO101: 0.95073892 | AP101: 0;566022925035471 | AQ101: 0;922494511084352 | AR101: 1 | AS101: 0;955912927985531 | AT101: 1 | AU101: 0;864140252612585 | AV101: 0;264091700141884 | AW101: 0;873260330881363 | AX101: 0 | AY101: =VLOOKUP(B101,[1]Página1!$A:$E,4,0) -> 7560145.1
A102: 3204401 | B102: RIO NOVO DO SUL | C102: 2023 | D102: 0.71191405 | E102: 0.69793346 | F102: 0.945 | G102: 0.54407085 | H102: 0.75804447 | I102: 0.60776693 | J102: 0.76187309 | K102: 0.7314085 | L102: 0.75421586 | M102: 0.48412537 | N102: 0.62497621 | O102: 0.61203039 | P102: 0.59378576 | Q102: 0.583735 | R102: 0.90225564 | S102: 0.067669173 | T102: 0.052631579 | U102: 0.32330827 | V102: 0.55639098 | W102: 0.87325457 | X102: 0.045112782 | Y102: 0.14285714 | Z102: 0.33834586 | AA102: 0.47368421 | AB102: 0.82312925 | AC102: 0.031746032 | AD102: 0.25396825 | AE102: 0.30952381 | AF102: 0.4047619 | AG102: 0.74943311 | AH102: 0.087301587 | AI102: 0.28571429 | AJ102: 0.43650794 | AK102: 0.19047619 | AL102: 0.91724138 | AM102: 0.91724138 | AN102: 0.96183206 | AO102: 0.96183206 | AP102: 0;544070847114976 | AQ102: 0;96578523977142 | AR102: 1 | AS102: 0;960028473861831 | AT102: 1 | AU102: 0;788957884761161 | AV102: 0;0157491209424424 | AW102: 0;868220575918509 | AX102: 0;160534267517463 | AY102: =VLOOKUP(B102,[1]Página1!$A:$E,4,0) -> 7664044.8
A103: 3205036 | B103: VARGEM ALTA | C103: 2023 | D103: 0.45121122 | E103: 0.44089038 | F103: 0.936 | G103: 0.014586381 | H103: 0.50619837 | I103: 0.34292838 | J103: 0.69779885 | K103: 0.68585676 | L103: 0.3145979 | M103: 0 | N103: 0.56619001 | O103: 0.51503649 | P103: 0.55914707 | Q103: 0.55498998 | R103: 0.82064651 | S103: 0.10218978 | T103: 0.1350365 | U103: 0.37956204 | V103: 0.38321168 | W103: 0.76293996 | X103: 0.094202899 | Y103: 0.25 | Z103: 0.44565217 | AA103: 0.21014493 | AB103: 0.77391304 | AC103: 0.086956522 | AD103: 0.24347826 | AE103: 0.37391304 | AF103: 0.29565217 | AG103: 0.68074534 | AH103: 0.11304348 | AI103: 0.36086957 | AJ103: 0.31304348 | AK103: 0.21304348 | AL103: 0.89836066 | AM103: 0.90789474 | AN103: 0.90196078 | AO103: 0.90196078 | AP103: 0;0145863811215223 | AQ103: 0;884149303819258 | AR103: 0;0583455244860892 | AS103: 0;871954570582868 | AT103: 0 | AU103: 0;845554627413473 | AV103: 0 | AW103: 0;826678852928019 | AX103: 0 | AY103: =VLOOKUP(B103,[1]Página1!$A:$E,4,0) -> 4857472.6
A104: 3202207 | B104: FUNDAO | C104: 2023 | D104: 0.69156125 | E104: 0.61443195 | F104: 0.953 | G104: 0.7900592 | H104: 0.52762587 | I104: 0.74464107 | J104: 0.66792849 | K104: 0.65374974 | L104: 0.38732325 | M104: 0.8355324 | N104: 0.52894825 | O104: 0.50779306 | P104: 0.5251122 | Q104: 0.51094512 | R104: 0.76254826 | S104: 0.13963964 | T104: 0.17117117 | U104: 0.38738739 | V104: 0.3018018 | W104: 0.78304406 | X104: 0.070093458 | Y104: 0.25700935 | Z104: 0.52803738 | AA104: 0.14485981 | AB104: 0.73728223 | AC104: 0.13170732 | AD104: 0.22926829 | AE104: 0.42439024 | AF104: 0.21463415 | AG104: 0.5902439 | AH104: 0.21463415 | AI104: 0.34146341 | AJ104: 0.31219512 | AK104: 0.13170732 | AL104: 0.8671875 | AM104: 0.84920635 | AN104: 0.91517857 | AO104: 0.91517857 | AP104: 0;790059197257429 | AQ104: 0;945533735015821 | AR104: 1 | AS104: 0;956159472174485 | AT104: 1 | AU104: 0;83885132032999 | AV104: 0;160236789029715 | AW104: 0;909128673664071 | AX104: 1 | AY104: =VLOOKUP(B104,[1]Página1!$A:$E,4,0) -> 7444938.6
A105: 3204609 | B105: SANTA TERESA | C105: 2023 | D105: 0.73563073 | E105: 0.75891443 | F105: 0.998 | G105: 0.36460423 | H105: 0.68729942 | I105: 0.86633693 | J105: 0.7434239 | K105: 0.75458694 | L105: 0.63117494 | M105: 0.97808692 | N105: 0.63129117 | O105: 0.57435995 | P105: 0.61774911 | Q105: 0.62667682 | R105: 0.91428571 | S105: 0.048648649 | T105: 0.064864865 | U105: 0.33513514 | V105: 0.55135135 | W105: 0.84011843 | X105: 0.041450777 | Y105: 0.20725389 | Z105: 0.37823834 | AA105: 0.37305699 | AB105: 0.86725067 | AC105: 0.051886793 | AD105: 0.14150943 | AE105: 0.3254717 | AF105: 0.48113208 | AG105: 0.78773585 | AH105: 0.080188679 | AI105: 0.23113208 | AJ105: 0.37264151 | AK105: 0.31603774 | AL105: 0.86046512 | AM105: 0.88940092 | AN105: 0.94642857 | AO105: 0.94642857 | AP105: 0;364604226122733 | AQ105: 0;898046581198893 | AR105: 0 | AS105: 0;922394792084692 | AT105: 1 | AU105: 0;879542064421801 | AV105: 0;443317193267901 | AW105: 0;844173673007101 | AX105: 0;0150997112230315 | AY105: =VLOOKUP(B105,[1]Página1!$A:$E,4,0) -> 7919364.5
...

Sheet Fato_Indicadores
A1: CodigoMunicipio | B1: Municipio | C1: Ano | D1: Indicador | E1: Valor | F1: Etapa | G1: Disciplina | H1: Tipo | I1: DataAtualizacao | J1: VersaoDados | K1: Fonte

Sheet Dim_Indicador
A1: Indicador | B1: NomeExibicao | C1: Definicao | D1: FormulaResumida | E1: NotasDeLeitura | F1: Tipo | G1: Etapa | H1: Disciplina
A2: IQE | B2: Índice de Qualidade Educacional | C2: Síntese de qualidade de aprendizagem, aprovação e equidade. | D2: IQE = 0,7·IQEF + 0,15·P + 0,15·IMEG | E2: Usar para visão geral e comparações entre municípios no ano. | F2: Sintese
A3: IQEF | B3: Índice de Qualidade do EF | C3: Qualidade da aprendizagem do EF, combinando 2º e 5º ano. | D3: IQEF = 0,6·IQ2 + 0,4·IQ5 | E3: Dá mais peso ao 2º ano (alfabetização). | F3: Sintese
A4: P | B4: Taxa de aprovação do EF | C4: Aprovação entre matriculados no EF do município. | D4: P = APR / (APR + REP + ABA) | E4: Aprovação alta com IDE baixo exige investigação. | F4: Aprovacao
A5: IMEG | B5: Melhoria da Equidade Global | C5: Equidade global do município no ano, normalizada entre municípios. | D5: IMEG = (IVEC − IVEC_min) / (IVEC_max − IVEC_min) | E5: Comparável dentro do ano; apoiar análise com IVEC e ΔDESV. | F5: Equidade
A6: IVEC | B6: Variação da Equidade Composta | C6: Média dos ganhos de equidade por etapa e disciplina. | D6: IVEC = média(ΔDESV_2LP, ΔDESV_2MT, ΔDESV_5LP, ΔDESV_5MT) | E6: Para evolução ‘bruta’ de equidade; IMEG é normalizado anual. | F6: Equidade
A7: IQ2 | B7: Índice do 2º ano | C7: Qualidade por etapa (2º ano). | D7: IQ2 = 0,5·IDE2 + 0,5·DeltaIDEN2 | E7: Equilibra nível e ganho anual. | F7: Etapa | G7: 2
A8: IQ5 | B8: Índice do 5º ano | C8: Qualidade por etapa (5º ano). | D8: IQ5 = 0,5·IDE5 + 0,5·DeltaIDEN5 | E8: Equilibra nível e ganho anual. | F8: Etapa | G8: 5
A9: IDE2 | B9: Índice de Desempenho 2º | C9: Nível atual de desempenho do 2º ano. | D9: IDE2 = 0,6·IDELP2 + 0,4·IDEMT2 | E9: Fotografia do nível (não melhoria). | F9: Etapa | G9: 2
A10: IDE5 | B10: Índice de Desempenho 5º | C10: Nível atual de desempenho do 5º ano. | D10: IDE5 = 0,5·IDELP5 + 0,5·IDEMT5 | E10: Fotografia do nível (não melhoria). | F10: Etapa | G10: 5
A11: DeltaIDEN2 | B11: Ganho anual do IDE (2º) | C11: Melhoria anual do IDE do 2º ano, normalizada (0 a 1). | D11: ΔIDEN2 = norm(IDE2_t − IDE2_t-1) | E11: Altos valores indicam avanço. | F11: Etapa | G11: 2
A12: DeltaIDEN5 | B12: Ganho anual do IDE (5º) | C12: Melhoria anual do IDE do 5º ano, normalizada (0 a 1). | D12: ΔIDEN5 = norm(IDE5_t − IDE5_t-1) | E12: Altos valores indicam avanço. | F12: Etapa | G12: 5
A13: IDELP2 | B13: IDE Língua Portuguesa 2º | C13: Índice por disciplina/etapa: PMN + IDA + TP. | D13: IDELP2 = 0,5·PMNLP2 + 0,25·IDALP2 + 0,25·TPLP2 | E13: TP também afeta o índice. | F13: Disciplina | G13: 2 | H13: LP
A14: IDELP5 | B14: IDE Língua Portuguesa 5º | C14: Índice por disciplina/etapa: PMN + IDA + TP. | D14: IDELP5 = 0,5·PMNLP5 + 0,25·IDALP5 + 0,25·TPLP5 | E14: TP também afeta o índice. | F14: Disciplina | G14: 5 | H14: LP
A15: IDEMT2 | B15: IDE Matemática 2º | C15: Índice por disciplina/etapa: PMN + IDA + TP. | D15: IDEMT2 = 0,5·PMNMT2 + 0,25·IDAMT2 + 0,25·TPMT2 | E15: TP também afeta o índice. | F15: Disciplina | G15: 2 | H15: MT
A16: IDEMT5 | B16: IDE Matemática 5º | C16: Índice por disciplina/etapa: PMN + IDA + TP. | D16: IDEMT5 = 0,5·PMNMT5 + 0,25·IDAMT5 + 0,25·TPMT5 | E16: TP também afeta o índice. | F16: Disciplina | G16: 5 | H16: MT
A17: PMN2 | B17: Proficiência Média Normalizada (2º) | C17: Agregado de PMN por etapa. | D17: PMN2 = 0,6·PMNLP2 + 0,4·PMNMT2 | E17: Normaliza proficiências por média/DP. | F17: Etapa | G17: 2
A18: PMN5 | B18: Proficiência Média Normalizada (5º) | C18: Agregado de PMN por etapa. | D18: PMN5 = 0,5·PMNLP5 + 0,5·PMNMT5 | E18: Normaliza proficiências por média/DP. | F18: Etapa | G18: 5
A19: IDA2 | B19: Distribuição nos Padrões (2º) | C19: Agregado de IDA por etapa. | D19: IDA2 = 0,6·IDALP2 + 0,4·IDAMT2 | E19: Mais alunos Profic./Avançado = melhor. | F19: Etapa | G19: 2
A20: IDA5 | B20: Distribuição nos Padrões (5º) | C20: Agregado de IDA por etapa. | D20: IDA5 = 0,5·IDALP5 + 0,5·IDAMT5 | E20: Mais alunos Profic./Avançado = melhor. | F20: Etapa | G20: 5
A21: PMNLP2 | B21: PMN Língua Portuguesa 2º | C21: Proficiência normalizada em LP no 2º ano. | D21: Padronização por média/DP de referência. | F21: Disciplina | G21: 2 | H21: LP
A22: PMNMT2 | B22: PMN Matemática 2º | C22: Proficiência normalizada em MT no 2º ano. | D22: Padronização por média/DP de referência. | F22: Disciplina | G22: 2 | H22: MT
A23: PMNLP5 | B23: PMN Língua Portuguesa 5º | C23: Proficiência normalizada em LP no 5º ano. | D23: Padronização por média/DP de referência. | F23: Disciplina | G23: 5 | H23: LP
A24: PMNMT5 | B24: PMN Matemática 5º | C24: Proficiência normalizada em MT no 5º ano. | D24: Padronização por média/DP de referência. | F24: Disciplina | G24: 5 | H24: MT
A25: IDALP2 | B25: IDA Língua Portuguesa 2º | C25: Distribuição em padrões (LP) no 2º ano. | D25: Peso maior para Proficiente/Avançado. | F25: Disciplina | G25: 2 | H25: LP
A26: IDAMT2 | B26: IDA Matemática 2º | C26: Distribuição em padrões (MT) no 2º ano. | D26: Peso maior para Proficiente/Avançado. | F26: Disciplina | G26: 2 | H26: MT
A27: IDALP5 | B27: IDA Língua Portuguesa 5º | C27: Distribuição em padrões (LP) no 5º ano. | D27: Peso maior para Proficiente/Avançado. | F27: Disciplina | G27: 5 | H27: LP
A28: IDAMT5 | B28: IDA Matemática 5º | C28: Distribuição em padrões (MT) no 5º ano. | D28: Peso maior para Proficiente/Avançado. | F28: Disciplina | G28: 5 | H28: MT
A29: TPLP2 | B29: Taxa de Participação LP 2º | C29: Participação dos alunos avaliados (LP) no 2º ano. | D29: Proporção de alunos avaliados. | F29: Participacao | G29: 2 | H29: LP
A30: TPMT2 | B30: Taxa de Participação MT 2º | C30: Participação dos alunos avaliados (MT) no 2º ano. | D30: Proporção de alunos avaliados. | F30: Participacao | G30: 2 | H30: MT
A31: TPLP5 | B31: Taxa de Participação LP 5º | C31: Participação dos alunos avaliados (LP) no 5º ano. | D31: Proporção de alunos avaliados. | F31: Participacao | G31: 5 | H31: LP
A32: TPMT5 | B32: Taxa de Participação MT 5º | C32: Participação dos alunos avaliados (MT) no 5º ano. | D32: Proporção de alunos avaliados. | F32: Participacao | G32: 5 | H32: MT

Sheet Dim_Municipio
A1: CodigoMunicipio | B1: Municipio | C1: Microrregiao | D1: Regiao | E1: UF

Sheet README
A1: Instruções
A2: MODELO DE DADOS PARA PAINEL IQE (ES)
A3: Como atualizar todo ano:
A4: 1) Acrescente novas linhas (Ano=2026, 2027, ...) em Base_Painel e Fato_Indicadores.
A5: 2) Use sempre os mesmos nomes de colunas; não mesclar células; não inserir linhas de títulos extras.
A6: 3) Deixe valores numéricos sem formatação de % (o BI formata).
A7: 4) 'Ano' em inteiro (ex.: 2024). Nulos = célula em branco.
A8: 5) Ranking e médias do ES são calculados no BI (não precisam estar aqui).
A9: 6) Chave recomendada: CodigoMunicipio (IBGE) + Ano.
A10: 7) DataAtualizacao e VersaoDados ajudam no controle de versões.
A11: 8) IMEG é normalizado por ano; para evolução da equidade apoiar-se em IVEC/ΔDESV.
A12: Modelo gerado em 2025-10-06.
