Workbook

Sheet 2022_2ANO_LP_LTR + ECT
A1: Tipo | B1: Código país | C1: País | D1: Código estado | E1: Estado | F1: Código regional | G1: Regional | H1: Código município | I1: Município | J1: Código escola | K1: Escola | L1: Código turma | M1: Turma | N1: Documento | O1: Edição | P1: Rede | Q1: Etapa | R1: Disciplina | S1: CD_ENSINO | T1: DC_ENSINO | U1: Previsto | V1: Efetivo | W1: Participação % | X1: Proficiência | Y1: Desvio Padrão | Z1: Padrão de Desempenho | AA1: Acertos no Teste % | AB1: Abaixo do Básico % | AC1: Básico % | AD1: Proficiente % | AE1: Avançado % | AF1: Abaixo do Básico | AG1: Básico | AH1: Proficiente | AI1: Avançado
A2: MUNICIPIO | B2: 01058 | C2: Brasil | D2: 32 | E2: ESPÍRITO SANTO | F2: 000037 | G2: SRE AFONSO CLAUDIO | H2: 3200102 | I2: AFONSO CLAUDIO | J2: - | K2: - | L2: - | M2: - | N2: 3200102 | O2: 2022 | P2: Municipal | Q2: ENSINO FUNDAMENTAL DE 9 ANOS - 2º ANO | R2: Língua Portuguesa - Escrita e Leitura | S2: 9 | T2: ENSINO FUNDAMENTAL | U2: 320 | V2: 295 | W2: 92.1875 | X2: 684.56171 | Y2: 90.317617 | Z2: Proficiente | AA2: 69.205084 | AB2: 0.050847458 | AC2: 0.091525424 | AD2: 0.40677966 | AE2: 0.45084746 | AF2: 15 | AG2: 27 | AH2: 120 | AI2: 133
A3: MUNICIPIO | B3: 01058 | C3: Brasil | D3: 32 | E3: ESPÍRITO SANTO | F3: 000037 | G3: SRE AFONSO CLAUDIO | H3: 3201159 | I3: BREJETUBA | J3: - | K3: - | L3: - | M3: - | N3: 3201159 | O3: 2022 | P3: Municipal | Q3: ENSINO FUNDAMENTAL DE 9 ANOS - 2º ANO | R3: Língua Portuguesa - Escrita e Leitura | S3: 9 | T3: ENSINO FUNDAMENTAL | U3: 169 | V3: 156 | W3: 92.307692 | X3: 656.07319 | Y3: 98.859791 | Z3: Proficiente | AA3: 64.291564 | AB3: 0.10897436 | AC3: 0.096153846 | AD3: 0.42948718 | AE3: 0.36538462 | AF3: 17 | AG3: 15 | AH3: 67 | AI3: 57
A4: MUNICIPIO | B4: 01058 | C4: Brasil | D4: 32 | E4: ESPÍRITO SANTO | F4: 000037 | G4: SRE AFONSO CLAUDIO | H4: 3201704 | I4: CONCEICAO DO CASTELO | J4: - | K4: - | L4: - | M4: - | N4: 3201704 | O4: 2022 | P4: Municipal | Q4: ENSINO FUNDAMENTAL DE 9 ANOS - 2º ANO | R4: Língua Portuguesa - Escrita e Leitura | S4: 9 | T4: ENSINO FUNDAMENTAL | U4: 188 | V4: 178 | W4: 94.680851 | X4: 655.30162 | Y4: 95.524977 | Z4: Proficiente | AA4: 63.456091 | AB4: 0.073033708 | AC4: 0.12359551 | AD4: 0.46629213 | AE4: 0.33707865 | AF4: 13 | AG4: 22 | AH4: 83 | AI4: 60
A5: MUNICIPIO | B5: 01058 | C5: Brasil | D5: 32 | E5: ESPÍRITO SANTO | F5: 000037 | G5: SRE AFONSO CLAUDIO | H5: 3201902 | I5: DOMINGOS MARTINS | J5: - | K5: - | L5: - | M5: - | N5: 3201902 | O5: 2022 | P5: Municipal | Q5: ENSINO FUNDAMENTAL DE 9 ANOS - 2º ANO | R5: Língua Portuguesa - Escrita e Leitura | S5: 9 | T5: ENSINO FUNDAMENTAL | U5: 465 | V5: 424 | W5: 91.182796 | X5: 663.06708 | Y5: 89.736497 | Z5: Proficiente | AA5: 63.242352 | AB5: 0.051886793 | AC5: 0.16037736 | AD5: 0.42216981 | AE5: 0.36556604 | AF5: 22 | AG5: 68 | AH5: 179 | AI5: 155
A6: MUNICIPIO | B6: 01058 | C6: Brasil | D6: 32 | E6: ESPÍRITO SANTO | F6: 000037 | G6: SRE AFONSO CLAUDIO | H6: 3203163 | I6: LARANJA DA TERRA | J6: - | K6: - | L6: - | M6: - | N6: 3203163 | O6: 2022 | P6: Municipal | Q6: ENSINO FUNDAMENTAL DE 9 ANOS - 2º ANO | R6: Língua Portuguesa - Escrita e Leitura | S6: 9 | T6: ENSINO FUNDAMENTAL | U6: 106 | V6: 97 | W6: 91.509434 | X6: 644.92397 | Y6: 90.102565 | Z6: Proficiente | AA6: 64.239691 | AB6: 0.06185567 | AC6: 0.24742268 | AD6: 0.37113402 | AE6: 0.31958763 | AF6: 6 | AG6: 24 | AH6: 36 | AI6: 31
A7: MUNICIPIO | B7: 01058 | C7: Brasil | D7: 32 | E7: ESPÍRITO SANTO | F7: 000037 | G7: SRE AFONSO CLAUDIO | H7: 3204559 | I7: SANTA MARIA DE JETIBA | J7: - | K7: - | L7: - | M7: - | N7: 3204559 | O7: 2022 | P7: Municipal | Q7: ENSINO FUNDAMENTAL DE 9 ANOS - 2º ANO | R7: Língua Portuguesa - Escrita e Leitura | S7: 9 | T7: ENSINO FUNDAMENTAL | U7: 312 | V7: 291 | W7: 93.269231 | X7: 632.46493 | Y7: 108.56623 | Z7: Proficiente | AA7: 59.522251 | AB7: 0.11340206 | AC7: 0.20274914 | AD7: 0.39862543 | AE7: 0.28522337 | AF7: 33 | AG7: 59 | AH7: 116 | AI7: 83
A8: MUNICIPIO | B8: 01058 | C8: Brasil | D8: 32 | E8: ESPÍRITO SANTO | F8: 000037 | G8: SRE AFONSO CLAUDIO | H8: 3205069 | I8: VENDA NOVA DO IMIGRANTE | J8: - | K8: - | L8: - | M8: - | N8: 3205069 | O8: 2022 | P8: Municipal | Q8: ENSINO FUNDAMENTAL DE 9 ANOS - 2º ANO | R8: Língua Portuguesa - Escrita e Leitura | S8: 9 | T8: ENSINO FUNDAMENTAL | U8: 166 | V8: 132 | W8: 79.518072 | X8: 634.47709 | Y8: 101.16981 | Z8: Proficiente | AA8: 60.785714 | AB8: 0.098484848 | AC8: 0.21212121 | AD8: 0.39393939 | AE8: 0.29545455 | AF8: 13 | AG8: 28 | AH8: 52 | AI8: 39
A9: MUNICIPIO | B9: 01058 | C9: Brasil | D9: 32 | E9: ESPÍRITO SANTO | F9: 000032 | G9: SRE BARRA DE SAO FRANCISCO | H9: 3200169 | I9: AGUA DOCE DO NORTE | J9: - | K9: - | L9: - | M9: - | N9: 3200169 | O9: 2022 | P9: Municipal | Q9: ENSINO FUNDAMENTAL DE 9 ANOS - 2º ANO | R9: Língua Portuguesa - Escrita e Leitura | S9: 9 | T9: ENSINO FUNDAMENTAL | U9: 162 | V9: 145 | W9: 89.506173 | X9: 607.27978 | Y9: 111.92576 | Z9: Proficiente | AA9: 51.137358 | AB9: 0.17931034 | AC9: 0.17241379 | AD9: 0.48275862 | AE9: 0.16551724 | AF9: 26 | AG9: 25 | AH9: 70 | AI9: 24
A10: MUNICIPIO | B10: 01058 | C10: Brasil | D10: 32 | E10: ESPÍRITO SANTO | F10: 000032 | G10: SRE BARRA DE SAO FRANCISCO | H10: 3200136 | I10: AGUIA BRANCA | J10: - | K10: - | L10: - | M10: - | N10: 3200136 | O10: 2022 | P10: Municipal | Q10: ENSINO FUNDAMENTAL DE 9 ANOS - 2º ANO | R10: Língua Portuguesa - Escrita e Leitura | S10: 9 | T10: ENSINO FUNDAMENTAL | U10: 166 | V10: 151 | W10: 90.963855 | X10: 652.03014 | Y10: 88.623368 | Z10: Proficiente | AA10: 66.828138 | AB10: 0.059602649 | AC10: 0.18543046 | AD10: 0.47019868 | AE10: 0.28476821 | AF10: 9 | AG10: 28 | AH10: 71 | AI10: 43
A11: MUNICIPIO | B11: 01058 | C11: Brasil | D11: 32 | E11: ESPÍRITO SANTO | F11: 000032 | G11: SRE BARRA DE SAO FRANCISCO | H11: 3200904 | I11: BARRA DE SAO FRANCISCO | J11: - | K11: - | L11: - | M11: - | N11: 3200904 | O11: 2022 | P11: Municipal | Q11: ENSINO FUNDAMENTAL DE 9 ANOS - 2º ANO | R11: Língua Portuguesa - Escrita e Leitura | S11: 9 | T11: ENSINO FUNDAMENTAL | U11: 495 | V11: 464 | W11: 93.737374 | X11: 638.18106 | Y11: 96.583836 | Z11: Proficiente | AA11: 60.193103 | AB11: 0.099137931 | AC11: 0.17025862 | AD11: 0.46982759 | AE11: 0.26077586 | AF11: 46 | AG11: 79 | AH11: 218 | AI11: 121
A12: MUNICIPIO | B12: 01058 | C12: Brasil | D12: 32 | E12: ESPÍRITO SANTO | F12: 000032 | G12: SRE BARRA DE SAO FRANCISCO | H12: 3202108 | I12: ECOPORANGA | J12: - | K12: - | L12: - | M12: - | N12: 3202108 | O12: 2022 | P12: Municipal | Q12: ENSINO FUNDAMENTAL DE 9 ANOS - 2º ANO | R12: Língua Portuguesa - Escrita e Leitura | S12: 9 | T12: ENSINO FUNDAMENTAL | U12: 228 | V12: 212 | W12: 92.982456 | X12: 613.9506 | Y12: 102.29572 | Z12: Proficiente | AA12: 52.93589 | AB12: 0.14622642 | AC12: 0.20754717 | AD12: 0.46698113 | AE12: 0.17924528 | AF12: 31 | AG12: 44 | AH12: 99 | AI12: 38
A13: MUNICIPIO | B13: 01058 | C13: Brasil | D13: 32 | E13: ESPÍRITO SANTO | F13: 000032 | G13: SRE BARRA DE SAO FRANCISCO | H13: 3203304 | I13: MANTENOPOLIS | J13: - | K13: - | L13: - | M13: - | N13: 3203304 | O13: 2022 | P13: Municipal | Q13: ENSINO FUNDAMENTAL DE 9 ANOS - 2º ANO | R13: Língua Portuguesa - Escrita e Leitura | S13: 9 | T13: ENSINO FUNDAMENTAL | U13: 215 | V13: 196 | W13: 91.162791 | X13: 655.01753 | Y13: 111.13568 | Z13: Proficiente | AA13: 65.33871 | AB13: 0.096938776 | AC13: 0.11734694 | AD13: 0.41836735 | AE13: 0.36734694 | AF13: 19 | AG13: 23 | AH13: 82 | AI13: 72
... A79: MUNICIPIO | B79: 01058 | C79: Brasil | D79: 32 | E79: ESPÍRITO SANTO | F79: 000028 | G79: SRE VILA VELHA | H79: 3205200 | I79: VILA VELHA | J79: - | K79: - | L79: - | M79: - | N79: 3205200 | O79: 2022 | P79: Municipal | Q79: ENSINO FUNDAMENTAL DE 9 ANOS - 2º ANO | R79: Língua Portuguesa - Escrita e Leitura | S79: 9 | T79: ENSINO FUNDAMENTAL | U79: 4555 | V79: 3974 | W79: 87.244786 | X79: 615.37111 | Y79: 107.70899 | Z79: Proficiente | AA79: 57.166201 | AB79: 0.15475591 | AC79: 0.21766482 | AD79: 0.41419225 | AE79: 0.21338702 | AF79: 615 | AG79: 865 | AH79: 1646 | AI79: 848

Sheet 2022_2ANO_MT
A1: Tipo | B1: Código país | C1: País | D1: Código estado | E1: Estado | F1: Código regional | G1: Regional | H1: Código município | I1: Município | J1: Código escola | K1: Escola | L1: Código turma | M1: Turma | N1: Documento | O1: Edição | P1: Rede | Q1: Etapa | R1: Disciplina | S1: CD_ENSINO | T1: DC_ENSINO | U1: Previsto | V1: Efetivo | W1: Participação % | X1: Proficiência | Y1: Desvio Padrão | Z1: Padrão de Desempenho | AA1: Acertos no Teste % | AB1: Abaixo do Básico % | AC1: Básico % | AD1: Proficiente % | AE1: Avançado % | AF1: Abaixo do Básico | AG1: Básico | AH1: Proficiente | AI1: Avançado
A2: MUNICIPIO | B2: 01058 | C2: Brasil | D2: 32 | E2: ESPÍRITO SANTO | F2: 000037 | G2: SRE AFONSO CLAUDIO | H2: 3200102 | I2: AFONSO CLAUDIO | J2: - | K2: - | L2: - | M2: - | N2: 3200102 | O2: 2022 | P2: Municipal | Q2: ENSINO FUNDAMENTAL DE 9 ANOS - 2º ANO | R2: Matemática | S2: 9 | T2: ENSINO FUNDAMENTAL | U2: 323 | V2: 301 | W2: 93.188854 | X2: 562.67515 | Y2: 84.308486 | Z2: Proficiente | AA2: 76.860465 | AB2: 0.03654485 | AC2: 0.17940199 | AD2: 0.40531561 | AE2: 0.37873754 | AF2: 11 | AG2: 54 | AH2: 122 | AI2: 114
A3: MUNICIPIO | B3: 01058 | C3: Brasil | D3: 32 | E3: ESPÍRITO SANTO | F3: 000037 | G3: SRE AFONSO CLAUDIO | H3: 3201159 | I3: BREJETUBA | J3: - | K3: - | L3: - | M3: - | N3: 3201159 | O3: 2022 | P3: Municipal | Q3: ENSINO FUNDAMENTAL DE 9 ANOS - 2º ANO | R3: Matemática | S3: 9 | T3: ENSINO FUNDAMENTAL | U3: 169 | V3: 155 | W3: 91.715976 | X3: 541.34674 | Y3: 74.842777 | Z3: Proficiente | AA3: 72.258065 | AB3: 0.04516129 | AC3: 0.25806452 | AD3: 0.49032258 | AE3: 0.20645161 | AF3: 7 | AG3: 40 | AH3: 76 | AI3: 32
A4: MUNICIPIO | B4: 01058 | C4: Brasil | D4: 32 | E4: ESPÍRITO SANTO | F4: 000037 | G4: SRE AFONSO CLAUDIO | H4: 3201704 | I4: CONCEICAO DO CASTELO | J4: - | K4: - | L4: - | M4: - | N4: 3201704 | O4: 2022 | P4: Municipal | Q4: ENSINO FUNDAMENTAL DE 9 ANOS - 2º ANO | R4: Matemática | S4: 9 | T4: ENSINO FUNDAMENTAL | U4: 190 | V4: 177 | W4: 93.157895 | X4: 559.12955 | Y4: 84.469124 | Z4: Proficiente | AA4: 77.344633 | AB4: 0.06779661 | AC4: 0.11299435 | AD4: 0.48587571 | AE4: 0.33333333 | AF4: 12 | AG4: 20 | AH4: 86 | AI4: 59
A5: MUNICIPIO | B5: 01058 | C5: Brasil | D5: 32 | E5: ESPÍRITO SANTO | F5: 000037 | G5: SRE AFONSO CLAUDIO | H5: 3201902 | I5: DOMINGOS MARTINS | J5: - | K5: - | L5: - | M5: - | N5: 3201902 | O5: 2022 | P5: Municipal | Q5: ENSINO FUNDAMENTAL DE 9 ANOS - 2º ANO | R5: Matemática | S5: 9 | T5: ENSINO FUNDAMENTAL | U5: 466 | V5: 426 | W5: 91.416309 | X5: 546.03008 | Y5: 74.266132 | Z5: Proficiente | AA5: 73.286385 | AB5: 0.037558685 | AC5: 0.20657277 | AD5: 0.55164319 | AE5: 0.20422535 | AF5: 16 | AG5: 88 | AH5: 235 | AI5: 87
A6: MUNICIPIO | B6: 01058 | C6: Brasil | D6: 32 | E6: ESPÍRITO SANTO | F6: 000037 | G6: SRE AFONSO CLAUDIO | H6: 3203163 | I6: LARANJA DA TERRA | J6: - | K6: - | L6: - | M6: - | N6: 3203163 | O6: 2022 | P6: Municipal | Q6: ENSINO FUNDAMENTAL DE 9 ANOS - 2º ANO | R6: Matemática | S6: 9 | T6: ENSINO FUNDAMENTAL | U6: 106 | V6: 96 | W6: 90.566038 | X6: 574.25346 | Y6: 70.734878 | Z6: Proficiente | AA6: 80.260417 | AB6: 0.020833333 | AC6: 0.14583333 | AD6: 0.41666667 | AE6: 0.41666667 | AF6: 2 | AG6: 14 | AH6: 40 | AI6: 40
A7: MUNICIPIO | B7: 01058 | C7: Brasil | D7: 32 | E7: ESPÍRITO SANTO | F7: 000037 | G7: SRE AFONSO CLAUDIO | H7: 3204559 | I7: SANTA MARIA DE JETIBA | J7: - | K7: - | L7: - | M7: - | N7: 3204559 | O7: 2022 | P7: Municipal | Q7: ENSINO FUNDAMENTAL DE 9 ANOS - 2º ANO | R7: Matemática | S7: 9 | T7: ENSINO FUNDAMENTAL | U7: 312 | V7: 295 | W7: 94.551282 | X7: 544.44444 | Y7: 87.447315 | Z7: Proficiente | AA7: 73 | AB7: 0.047457627 | AC7: 0.26101695 | AD7: 0.38305085 | AE7: 0.30847458 | AF7: 14 | AG7: 77 | AH7: 113 | AI7: 91
A8: MUNICIPIO | B8: 01058 | C8: Brasil | D8: 32 | E8: ESPÍRITO SANTO | F8: 000037 | G8: SRE AFONSO CLAUDIO | H8: 3205069 | I8: VENDA NOVA DO IMIGRANTE | J8: - | K8: - | L8: - | M8: - | N8: 3205069 | O8: 2022 | P8: Municipal | Q8: ENSINO FUNDAMENTAL DE 9 ANOS - 2º ANO | R8: Matemática | S8: 9 | T8: ENSINO FUNDAMENTAL | U8: 166 | V8: 132 | W8: 79.518072 | X8: 502.01215 | Y8: 79.192807 | Z8: Proficiente | AA8: 63.901515 | AB8: 0.098484848 | AC8: 0.35606061 | AD8: 0.46969697 | AE8: 0.075757576 | AF8: 13 | AG8: 47 | AH8: 62 | AI8: 10
A9: MUNICIPIO | B9: 01058 | C9: Brasil | D9: 32 | E9: ESPÍRITO SANTO | F9: 000032 | G9: SRE BARRA DE SAO FRANCISCO | H9: 3200169 | I9: AGUA DOCE DO NORTE | J9: - | K9: - | L9: - | M9: - | N9: 3200169 | O9: 2022 | P9: Municipal | Q9: ENSINO FUNDAMENTAL DE 9 ANOS - 2º ANO | R9: Matemática | S9: 9 | T9: ENSINO FUNDAMENTAL | U9: 162 | V9: 142 | W9: 87.654321 | X9: 489.06568 | Y9: 79.424136 | Z9: Básico | AA9: 61.971831 | AB9: 0.14084507 | AC9: 0.4084507 | AD9: 0.38028169 | AE9: 0.070422535 | AF9: 20 | AG9: 58 | AH9: 54 | AI9: 10
A10: MUNICIPIO | B10: 01058 | C10: Brasil | D10: 32 | E10: ESPÍRITO SANTO | F10: 000032 | G10: SRE BARRA DE SAO FRANCISCO | H10: 3200136 | I10: AGUIA BRANCA | J10: - | K10: - | L10: - | M10: - | N10: 3200136 | O10: 2022 | P10: Municipal | Q10: ENSINO FUNDAMENTAL DE 9 ANOS - 2º ANO | R10: Matemática | S10: 9 | T10: ENSINO FUNDAMENTAL | U10: 166 | V10: 150 | W10: 90.361446 | X10: 593.27235 | Y10: 83.876288 | Z10: Proficiente | AA10: 83.166667 | AB10: 0.033333333 | AC10: 0.10666667 | AD10: 0.32666667 | AE10: 0.53333333 | AF10: 5 | AG10: 16 | AH10: 49 | AI10: 80
A11: MUNICIPIO | B11: 01058 | C11: Brasil | D11: 32 | E11: ESPÍRITO SANTO | F11: 000032 | G11: SRE BARRA DE SAO FRANCISCO | H11: 3200904 | I11: BARRA DE SAO FRANCISCO | J11: - | K11: - | L11: - | M11: - | N11: 3200904 | O11: 2022 | P11: Municipal | Q11: ENSINO FUNDAMENTAL DE 9 ANOS - 2º ANO | R11: Matemática | S11: 9 | T11: ENSINO FUNDAMENTAL | U11: 497 | V11: 464 | W11: 93.360161 | X11: 544.24046 | Y11: 85.107519 | Z11: Proficiente | AA11: 73.556034 | AB11: 0.051724138 | AC11: 0.23060345 | AD11: 0.45689655 | AE11: 0.26077586 | AF11: 24 | AG11: 107 | AH11: 212 | AI11: 121
A12: MUNICIPIO | B12: 01058 | C12: Brasil | D12: 32 | E12: ESPÍRITO SANTO | F12: 000032 | G12: SRE BARRA DE SAO FRANCISCO | H12: 3202108 | I12: ECOPORANGA | J12: - | K12: - | L12: - | M12: - | N12: 3202108 | O12: 2022 | P12: Municipal | Q12: ENSINO FUNDAMENTAL DE 9 ANOS - 2º ANO | R12: Matemática | S12: 9 | T12: ENSINO FUNDAMENTAL | U12: 227 | V12: 210 | W12: 92.511013 | X12: 500.15426 | Y12: 80.972385 | Z12: Básico | AA12: 64.5 | AB12: 0.1 | AC12: 0.4 | AD12: 0.38571429 | AE12: 0.11428571 | AF12: 21 | AG12: 84 | AH12: 81 | AI12: 24
A13: MUNICIPIO | B13: 01058 | C13: Brasil | D13: 32 | E13: ESPÍRITO SANTO | F13: 000032 | G13: SRE BARRA DE SAO FRANCISCO | H13: 3203304 | I13: MANTENOPOLIS | J13: - | K13: - | L13: - | M13: - | N13: 3203304 | O13: 2022 | P13: Municipal | Q13: ENSINO FUNDAMENTAL DE 9 ANOS - 2º ANO | R13: Matemática | S13: 9 | T13: ENSINO FUNDAMENTAL | U13: 215 | V13: 194 | W13: 90.232558 | X13: 571.00063 | Y13: 96.738483 | Z13: Proficiente | AA13: 77.319588 | AB13: 0.056701031 | AC13: 0.21649485 | AD13: 0.28350515 | AE13: 0.44329897 | AF13: 11 | AG13: 42 | AH13: 55 | AI13: 86
... A79: MUNICIPIO | B79: 01058 | C79: Brasil | D79: 32 | E79: ESPÍRITO SANTO | F79: 000028 | G79: SRE VILA VELHA | H79: 3205200 | I79: VILA VELHA | J79: - | K79: - | L79: - | M79: - | N79: 3205200 | O79: 2022 | P79: Municipal | Q79: ENSINO FUNDAMENTAL DE 9 ANOS - 2º ANO | R79: Matemática | S79: 9 | T79: ENSINO FUNDAMENTAL | U79: 4548 | V79: 3972 | W79: 87.335092 | X79: 517.32361 | Y79: 90.608332 | Z79: Proficiente | AA79: 67.240685 | AB79: 0.092145015 | AC79: 0.32426989 | AD79: 0.40684794 | AE79: 0.17673716 | AF79: 366 | AG79: 1288 | AH79: 1616 | AI79: 702

Sheet 2022_5ANO_LP
A1: Tipo | B1: Código país | C1: País | D1: Código estado | E1: Estado | F1: Código regional | G1: Regional | H1: Código município | I1: Município | J1: Código escola | K1: Escola | L1: Código turma | M1: Turma | N1: Documento | O1: Edição | P1: Rede | Q1: Etapa | R1: Disciplina | S1: CD_ENSINO | T1: DC_ENSINO | U1: Previsto | V1: Efetivo | W1: Participação % | X1: Proficiência | Y1: Desvio Padrão | Z1: Padrão de Desempenho | AA1: Acertos no Teste % | AB1: Abaixo do Básico % | AC1: Básico % | AD1: Proficiente % | AE1: Avançado % | AF1: Abaixo do Básico | AG1: Básico | AH1: Proficiente | AI1: Avançado
A2: MUNICIPIO | B2: 01058 | C2: Brasil | D2: 32 | E2: ESPÍRITO SANTO | F2: 000037 | G2: SRE AFONSO CLAUDIO | H2: 3200102 | I2: AFONSO CLAUDIO | J2: - | K2: - | L2: - | M2: - | N2: 3200102 | O2: 2022 | P2: Municipal | Q2: ENSINO FUNDAMENTAL DE 9 ANOS - 5º ANO | R2: Língua Portuguesa | S2: 9 | T2: ENSINO FUNDAMENTAL | U2: 325 | V2: 291 | W2: 89.538462 | X2: 219.14202 | Y2: 49.001194 | Z2: Proficiente | AA2: 62.933458 | AB2: 0.089347079 | AC2: 0.28865979 | AD2: 0.35738832 | AE2: 0.26460481 | AF2: 26 | AG2: 84 | AH2: 104 | AI2: 77
A3: MUNICIPIO | B3: 01058 | C3: Brasil | D3: 32 | E3: ESPÍRITO SANTO | F3: 000037 | G3: SRE AFONSO CLAUDIO | H3: 3201159 | I3: BREJETUBA | J3: - | K3: - | L3: - | M3: - | N3: 3201159 | O3: 2022 | P3: Municipal | Q3: ENSINO FUNDAMENTAL DE 9 ANOS - 5º ANO | R3: Língua Portuguesa | S3: 9 | T3: ENSINO FUNDAMENTAL | U3: 179 | V3: 160 | W3: 89.385475 | X3: 209.64992 | Y3: 47.797145 | Z3: Proficiente | AA3: 59.034091 | AB3: 0.10625 | AC3: 0.3125 | AD3: 0.375 | AE3: 0.20625 | AF3: 17 | AG3: 50 | AH3: 60 | AI3: 33
A4: MUNICIPIO | B4: 01058 | C4: Brasil | D4: 32 | E4: ESPÍRITO SANTO | F4: 000037 | G4: SRE AFONSO CLAUDIO | H4: 3201704 | I4: CONCEICAO DO CASTELO | J4: - | K4: - | L4: - | M4: - | N4: 3201704 | O4: 2022 | P4: Municipal | Q4: ENSINO FUNDAMENTAL DE 9 ANOS - 5º ANO | R4: Língua Portuguesa | S4: 9 | T4: ENSINO FUNDAMENTAL | U4: 174 | V4: 162 | W4: 93.103448 | X4: 214.79116 | Y4: 48.947958 | Z4: Proficiente | AA4: 61.672278 | AB4: 0.086419753 | AC4: 0.32098765 | AD4: 0.38271605 | AE4: 0.20987654 | AF4: 14 | AG4: 52 | AH4: 62 | AI4: 34
A5: MUNICIPIO | B5: 01058 | C5: Brasil | D5: 32 | E5: ESPÍRITO SANTO | F5: 000037 | G5: SRE AFONSO CLAUDIO | H5: 3201902 | I5: DOMINGOS MARTINS | J5: - | K5: - | L5: - | M5: - | N5: 3201902 | O5: 2022 | P5: Municipal | Q5: ENSINO FUNDAMENTAL DE 9 ANOS - 5º ANO | R5: Língua Portuguesa | S5: 9 | T5: ENSINO FUNDAMENTAL | U5: 441 | V5: 413 | W5: 93.650794 | X5: 214.26583 | Y5: 47.598538 | Z5: Proficiente | AA5: 60.862866 | AB5: 0.10895884 | AC5: 0.28087167 | AD5: 0.36319613 | AE5: 0.24697337 | AF5: 45 | AG5: 116 | AH5: 150 | AI5: 102
A6: MUNICIPIO | B6: 01058 | C6: Brasil | D6: 32 | E6: ESPÍRITO SANTO | F6: 000037 | G6: SRE AFONSO CLAUDIO | H6: 3203163 | I6: LARANJA DA TERRA | J6: - | K6: - | L6: - | M6: - | N6: 3203163 | O6: 2022 | P6: Municipal | Q6: ENSINO FUNDAMENTAL DE 9 ANOS - 5º ANO | R6: Língua Portuguesa | S6: 9 | T6: ENSINO FUNDAMENTAL | U6: 136 | V6: 133 | W6: 97.794118 | X6: 230.15159 | Y6: 48.734851 | Z6: Proficiente | AA6: 67.019822 | AB6: 0.037593985 | AC6: 0.2406015 | AD6: 0.37593985 | AE6: 0.34586466 | AF6: 5 | AG6: 32 | AH6: 50 | AI6: 46
A7: MUNICIPIO | B7: 01058 | C7: Brasil | D7: 32 | E7: ESPÍRITO SANTO | F7: 000037 | G7: SRE AFONSO CLAUDIO | H7: 3204559 | I7: SANTA MARIA DE JETIBA | J7: - | K7: - | L7: - | M7: - | N7: 3204559 | O7: 2022 | P7: Municipal | Q7: ENSINO FUNDAMENTAL DE 9 ANOS - 5º ANO | R7: Língua Portuguesa | S7: 9 | T7: ENSINO FUNDAMENTAL | U7: 304 | V7: 276 | W7: 90.789474 | X7: 218.51941 | Y7: 44.343277 | Z7: Proficiente | AA7: 62.088274 | AB7: 0.047101449 | AC7: 0.30434783 | AD7: 0.4057971 | AE7: 0.24275362 | AF7: 13 | AG7: 84 | AH7: 112 | AI7: 67
A8: MUNICIPIO | B8: 01058 | C8: Brasil | D8: 32 | E8: ESPÍRITO SANTO | F8: 000037 | G8: SRE AFONSO CLAUDIO | H8: 3205069 | I8: VENDA NOVA DO IMIGRANTE | J8: - | K8: - | L8: - | M8: - | N8: 3205069 | O8: 2022 | P8: Municipal | Q8: ENSINO FUNDAMENTAL DE 9 ANOS - 5º ANO | R8: Língua Portuguesa | S8: 9 | T8: ENSINO FUNDAMENTAL | U8: 111 | V8: 102 | W8: 91.891892 | X8: 220.37443 | Y8: 50.407608 | Z8: Proficiente | AA8: 63.368984 | AB8: 0.088235294 | AC8: 0.2745098 | AD8: 0.32352941 | AE8: 0.31372549 | AF8: 9 | AG8: 28 | AH8: 33 | AI8: 32
A9: MUNICIPIO | B9: 01058 | C9: Brasil | D9: 32 | E9: ESPÍRITO SANTO | F9: 000032 | G9: SRE BARRA DE SAO FRANCISCO | H9: 3200169 | I9: AGUA DOCE DO NORTE | J9: - | K9: - | L9: - | M9: - | N9: 3200169 | O9: 2022 | P9: Municipal | Q9: ENSINO FUNDAMENTAL DE 9 ANOS - 5º ANO | R9: Língua Portuguesa | S9: 9 | T9: ENSINO FUNDAMENTAL | U9: 183 | V9: 171 | W9: 93.442623 | X9: 212.35423 | Y9: 52.226613 | Z9: Proficiente | AA9: 59.383307 | AB9: 0.12280702 | AC9: 0.32163743 | AD9: 0.29239766 | AE9: 0.26315789 | AF9: 21 | AG9: 55 | AH9: 50 | AI9: 45
A10: MUNICIPIO | B10: 01058 | C10: Brasil | D10: 32 | E10: ESPÍRITO SANTO | F10: 000032 | G10: SRE BARRA DE SAO FRANCISCO | H10: 3200136 | I10: AGUIA BRANCA | J10: - | K10: - | L10: - | M10: - | N10: 3200136 | O10: 2022 | P10: Municipal | Q10: ENSINO FUNDAMENTAL DE 9 ANOS - 5º ANO | R10: Língua Portuguesa | S10: 9 | T10: ENSINO FUNDAMENTAL | U10: 142 | V10: 134 | W10: 94.366197 | X10: 215.37932 | Y10: 48.80177 | Z10: Proficiente | AA10: 61.770692 | AB10: 0.1119403 | AC10: 0.23880597 | AD10: 0.44029851 | AE10: 0.20895522 | AF10: 15 | AG10: 32 | AH10: 59 | AI10: 28
A11: MUNICIPIO | B11: 01058 | C11: Brasil | D11: 32 | E11: ESPÍRITO SANTO | F11: 000032 | G11: SRE BARRA DE SAO FRANCISCO | H11: 3200904 | I11: BARRA DE SAO FRANCISCO | J11: - | K11: - | L11: - | M11: - | N11: 3200904 | O11: 2022 | P11: Municipal | Q11: ENSINO FUNDAMENTAL DE 9 ANOS - 5º ANO | R11: Língua Portuguesa | S11: 9 | T11: ENSINO FUNDAMENTAL | U11: 491 | V11: 465 | W11: 94.704684 | X11: 214.93803 | Y11: 50.536834 | Z11: Proficiente | AA11: 61.505376 | AB11: 0.12043011 | AC11: 0.26666667 | AD11: 0.35268817 | AE11: 0.26021505 | AF11: 56 | AG11: 124 | AH11: 164 | AI11: 121
A12: MUNICIPIO | B12: 01058 | C12: Brasil | D12: 32 | E12: ESPÍRITO SANTO | F12: 000032 | G12: SRE BARRA DE SAO FRANCISCO | H12: 3202108 | I12: ECOPORANGA | J12: - | K12: - | L12: - | M12: - | N12: 3202108 | O12: 2022 | P12: Municipal | Q12: ENSINO FUNDAMENTAL DE 9 ANOS - 5º ANO | R12: Língua Portuguesa | S12: 9 | T12: ENSINO FUNDAMENTAL | U12: 194 | V12: 174 | W12: 89.690722 | X12: 207.48351 | Y12: 51.841502 | Z12: Proficiente | AA12: 57.392894 | AB12: 0.16666667 | AC12: 0.3045977 | AD12: 0.29310345 | AE12: 0.23563218 | AF12: 29 | AG12: 53 | AH12: 51 | AI12: 41
A13: MUNICIPIO | B13: 01058 | C13: Brasil | D13: 32 | E13: ESPÍRITO SANTO | F13: 000032 | G13: SRE BARRA DE SAO FRANCISCO | H13: 3203304 | I13: MANTENOPOLIS | J13: - | K13: - | L13: - | M13: - | N13: 3203304 | O13: 2022 | P13: Municipal | Q13: ENSINO FUNDAMENTAL DE 9 ANOS - 5º ANO | R13: Língua Portuguesa | S13: 9 | T13: ENSINO FUNDAMENTAL | U13: 199 | V13: 170 | W13: 85.427136 | X13: 222.33366 | Y13: 50.669204 | Z13: Proficiente | AA13: 64.491979 | AB13: 0.1 | AC13: 0.23529412 | AD13: 0.36470588 | AE13: 0.3 | AF13: 17 | AG13: 40 | AH13: 62 | AI13: 51
... A79: MUNICIPIO | B79: 01058 | C79: Brasil | D79: 32 | E79: ESPÍRITO SANTO | F79: 000028 | G79: SRE VILA VELHA | H79: 3205200 | I79: VILA VELHA | J79: - | K79: - | L79: - | M79: - | N79: 3205200 | O79: 2022 | P79: Municipal | Q79: ENSINO FUNDAMENTAL DE 9 ANOS - 5º ANO | R79: Língua Portuguesa | S79: 9 | T79: ENSINO FUNDAMENTAL | U79: 5105 | V79: 4473 | W79: 87.61998 | X79: 205.18592 | Y79: 52.304272 | Z79: Proficiente | AA79: 56.996525 | AB79: 0.16320143 | AC79: 0.30382294 | AD79: 0.3261793 | AE79: 0.20679633 | AF79: 730 | AG79: 1359 | AH79: 1459 | AI79: 925

Sheet 2022_5ANO_MT
A1: Tipo | B1: Código país | C1: País | D1: Código estado | E1: Estado | F1: Código regional | G1: Regional | H1: Código município | I1: Município | J1: Código escola | K1: Escola | L1: Código turma | M1: Turma | N1: Documento | O1: Edição | P1: Rede | Q1: Etapa | R1: Disciplina | S1: CD_ENSINO | T1: DC_ENSINO | U1: Previsto | V1: Efetivo | W1: Participação % | X1: Proficiência | Y1: Desvio Padrão | Z1: Padrão de Desempenho | AA1: Acertos no Teste % | AB1: Abaixo do Básico % | AC1: Básico % | AD1: Proficiente % | AE1: Avançado % | AF1: Abaixo do Básico | AG1: Básico | AH1: Proficiente | AI1: Avançado
A2: MUNICIPIO | B2: 01058 | C2: Brasil | D2: 32 | E2: ESPÍRITO SANTO | F2: 000037 | G2: SRE AFONSO CLAUDIO | H2: 3200102 | I2: AFONSO CLAUDIO | J2: - | K2: - | L2: - | M2: - | N2: 3200102 | O2: 2022 | P2: Municipal | Q2: ENSINO FUNDAMENTAL DE 9 ANOS - 5º ANO | R2: Matemática | S2: 9 | T2: ENSINO FUNDAMENTAL | U2: 325 | V2: 291 | W2: 89.538462 | X2: 235.4825 | Y2: 46.402623 | Z2: Proficiente | AA2: 52.936582 | AB2: 0.12371134 | AC2: 0.32646048 | AD2: 0.36082474 | AE2: 0.18900344 | AF2: 36 | AG2: 95 | AH2: 105 | AI2: 55
A3: MUNICIPIO | B3: 01058 | C3: Brasil | D3: 32 | E3: ESPÍRITO SANTO | F3: 000037 | G3: SRE AFONSO CLAUDIO | H3: 3201159 | I3: BREJETUBA | J3: - | K3: - | L3: - | M3: - | N3: 3201159 | O3: 2022 | P3: Municipal | Q3: ENSINO FUNDAMENTAL DE 9 ANOS - 5º ANO | R3: Matemática | S3: 9 | T3: ENSINO FUNDAMENTAL | U3: 179 | V3: 160 | W3: 89.385475 | X3: 227.19247 | Y3: 51.677041 | Z3: Proficiente | AA3: 50.056818 | AB3: 0.175 | AC3: 0.3 | AD3: 0.34375 | AE3: 0.18125 | AF3: 28 | AG3: 48 | AH3: 55 | AI3: 29
A4: MUNICIPIO | B4: 01058 | C4: Brasil | D4: 32 | E4: ESPÍRITO SANTO | F4: 000037 | G4: SRE AFONSO CLAUDIO | H4: 3201704 | I4: CONCEICAO DO CASTELO | J4: - | K4: - | L4: - | M4: - | N4: 3201704 | O4: 2022 | P4: Municipal | Q4: ENSINO FUNDAMENTAL DE 9 ANOS - 5º ANO | R4: Matemática | S4: 9 | T4: ENSINO FUNDAMENTAL | U4: 174 | V4: 162 | W4: 93.103448 | X4: 226.85856 | Y4: 46.495637 | Z4: Proficiente | AA4: 49.943883 | AB4: 0.14197531 | AC4: 0.39506173 | AD4: 0.2962963 | AE4: 0.16666667 | AF4: 23 | AG4: 64 | AH4: 48 | AI4: 27
A5: MUNICIPIO | B5: 01058 | C5: Brasil | D5: 32 | E5: ESPÍRITO SANTO | F5: 000037 | G5: SRE AFONSO CLAUDIO | H5: 3201902 | I5: DOMINGOS MARTINS | J5: - | K5: - | L5: - | M5: - | N5: 3201902 | O5: 2022 | P5: Municipal | Q5: ENSINO FUNDAMENTAL DE 9 ANOS - 5º ANO | R5: Matemática | S5: 9 | T5: ENSINO FUNDAMENTAL | U5: 441 | V5: 413 | W5: 93.650794 | X5: 228.05281 | Y5: 45.435467 | Z5: Proficiente | AA5: 49.438697 | AB5: 0.15012107 | AC5: 0.29539952 | AD5: 0.40435835 | AE5: 0.15012107 | AF5: 62 | AG5: 122 | AH5: 167 | AI5: 62
A6: MUNICIPIO | B6: 01058 | C6: Brasil | D6: 32 | E6: ESPÍRITO SANTO | F6: 000037 | G6: SRE AFONSO CLAUDIO | H6: 3203163 | I6: LARANJA DA TERRA | J6: - | K6: - | L6: - | M6: - | N6: 3203163 | O6: 2022 | P6: Municipal | Q6: ENSINO FUNDAMENTAL DE 9 ANOS - 5º ANO | R6: Matemática | S6: 9 | T6: ENSINO FUNDAMENTAL | U6: 136 | V6: 133 | W6: 97.794118 | X6: 241.79232 | Y6: 49.547151 | Z6: Proficiente | AA6: 55.70745 | AB6: 0.14285714 | AC6: 0.20300752 | AD6: 0.42105263 | AE6: 0.23308271 | AF6: 19 | AG6: 27 | AH6: 56 | AI6: 31
A7: MUNICIPIO | B7: 01058 | C7: Brasil | D7: 32 | E7: ESPÍRITO SANTO | F7: 000037 | G7: SRE AFONSO CLAUDIO | H7: 3204559 | I7: SANTA MARIA DE JETIBA | J7: - | K7: - | L7: - | M7: - | N7: 3204559 | O7: 2022 | P7: Municipal | Q7: ENSINO FUNDAMENTAL DE 9 ANOS - 5º ANO | R7: Matemática | S7: 9 | T7: ENSINO FUNDAMENTAL | U7: 304 | V7: 276 | W7: 90.789474 | X7: 235.65384 | Y7: 46.187087 | Z7: Proficiente | AA7: 53.227931 | AB7: 0.094202899 | AC7: 0.32971014 | AD7: 0.39130435 | AE7: 0.18478261 | AF7: 26 | AG7: 91 | AH7: 108 | AI7: 51
A8: MUNICIPIO | B8: 01058 | C8: Brasil | D8: 32 | E8: ESPÍRITO SANTO | F8: 000037 | G8: SRE AFONSO CLAUDIO | H8: 3205069 | I8: VENDA NOVA DO IMIGRANTE | J8: - | K8: - | L8: - | M8: - | N8: 3205069 | O8: 2022 | P8: Municipal | Q8: ENSINO FUNDAMENTAL DE 9 ANOS - 5º ANO | R8: Matemática | S8: 9 | T8: ENSINO FUNDAMENTAL | U8: 111 | V8: 102 | W8: 91.891892 | X8: 218.61434 | Y8: 50.072971 | Z8: Básico | AA8: 47.370766 | AB8: 0.24509804 | AC8: 0.31372549 | AD8: 0.29411765 | AE8: 0.14705882 | AF8: 25 | AG8: 32 | AH8: 30 | AI8: 15
A9: MUNICIPIO | B9: 01058 | C9: Brasil | D9: 32 | E9: ESPÍRITO SANTO | F9: 000032 | G9: SRE BARRA DE SAO FRANCISCO | H9: 3200169 | I9: AGUA DOCE DO NORTE | J9: - | K9: - | L9: - | M9: - | N9: 3200169 | O9: 2022 | P9: Municipal | Q9: ENSINO FUNDAMENTAL DE 9 ANOS - 5º ANO | R9: Matemática | S9: 9 | T9: ENSINO FUNDAMENTAL | U9: 183 | V9: 171 | W9: 93.442623 | X9: 227.19045 | Y9: 46.86555 | Z9: Proficiente | AA9: 49.973418 | AB9: 0.12865497 | AC9: 0.34502924 | AD9: 0.39766082 | AE9: 0.12865497 | AF9: 22 | AG9: 59 | AH9: 68 | AI9: 22
A10: MUNICIPIO | B10: 01058 | C10: Brasil | D10: 32 | E10: ESPÍRITO SANTO | F10: 000032 | G10: SRE BARRA DE SAO FRANCISCO | H10: 3200136 | I10: AGUIA BRANCA | J10: - | K10: - | L10: - | M10: - | N10: 3200136 | O10: 2022 | P10: Municipal | Q10: ENSINO FUNDAMENTAL DE 9 ANOS - 5º ANO | R10: Matemática | S10: 9 | T10: ENSINO FUNDAMENTAL | U10: 142 | V10: 134 | W10: 94.366197 | X10: 231.61332 | Y10: 46.310181 | Z10: Proficiente | AA10: 52.001357 | AB10: 0.11940299 | AC10: 0.32835821 | AD10: 0.37313433 | AE10: 0.17910448 | AF10: 16 | AG10: 44 | AH10: 50 | AI10: 24
A11: MUNICIPIO | B11: 01058 | C11: Brasil | D11: 32 | E11: ESPÍRITO SANTO | F11: 000032 | G11: SRE BARRA DE SAO FRANCISCO | H11: 3200904 | I11: BARRA DE SAO FRANCISCO | J11: - | K11: - | L11: - | M11: - | N11: 3200904 | O11: 2022 | P11: Municipal | Q11: ENSINO FUNDAMENTAL DE 9 ANOS - 5º ANO | R11: Matemática | S11: 9 | T11: ENSINO FUNDAMENTAL | U11: 491 | V11: 465 | W11: 94.704684 | X11: 229.12459 | Y11: 45.404895 | Z11: Proficiente | AA11: 51.11437 | AB11: 0.1483871 | AC11: 0.31827957 | AD11: 0.36344086 | AE11: 0.16989247 | AF11: 69 | AG11: 148 | AH11: 169 | AI11: 79
A12: MUNICIPIO | B12: 01058 | C12: Brasil | D12: 32 | E12: ESPÍRITO SANTO | F12: 000032 | G12: SRE BARRA DE SAO FRANCISCO | H12: 3202108 | I12: ECOPORANGA | J12: - | K12: - | L12: - | M12: - | N12: 3202108 | O12: 2022 | P12: Municipal | Q12: ENSINO FUNDAMENTAL DE 9 ANOS - 5º ANO | R12: Matemática | S12: 9 | T12: ENSINO FUNDAMENTAL | U12: 194 | V12: 175 | W12: 90.206186 | X12: 214.9915 | Y12: 49.141849 | Z12: Básico | AA12: 44.623377 | AB12: 0.24 | AC12: 0.37714286 | AD12: 0.25142857 | AE12: 0.13142857 | AF12: 42 | AG12: 66 | AH12: 44 | AI12: 23
A13: MUNICIPIO | B13: 01058 | C13: Brasil | D13: 32 | E13: ESPÍRITO SANTO | F13: 000032 | G13: SRE BARRA DE SAO FRANCISCO | H13: 3203304 | I13: MANTENOPOLIS | J13: - | K13: - | L13: - | M13: - | N13: 3203304 | O13: 2022 | P13: Municipal | Q13: ENSINO FUNDAMENTAL DE 9 ANOS - 5º ANO | R13: Matemática | S13: 9 | T13: ENSINO FUNDAMENTAL | U13: 199 | V13: 170 | W13: 85.427136 | X13: 239.09166 | Y13: 47.514123 | Z13: Proficiente | AA13: 54.86631 | AB13: 0.088235294 | AC13: 0.31176471 | AD13: 0.4 | AE13: 0.2 | AF13: 15 | AG13: 53 | AH13: 68 | AI13: 34
... A79: MUNICIPIO | B79: 01058 | C79: Brasil | D79: 32 | E79: ESPÍRITO SANTO | F79: 000028 | G79: SRE VILA VELHA | H79: 3205200 | I79: VILA VELHA | J79: - | K79: - | L79: - | M79: - | N79: 3205200 | O79: 2022 | P79: Municipal | Q79: ENSINO FUNDAMENTAL DE 9 ANOS - 5º ANO | R79: Matemática | S79: 9 | T79: ENSINO FUNDAMENTAL | U79: 5105 | V79: 4465 | W79: 87.463271 | X79: 214.79109 | Y79: 45.017499 | Z79: Básico | AA79: 44.643184 | AB79: 0.20604703 | AC79: 0.39753639 | AD79: 0.29697648 | AE79: 0.09944009 | AF79: 920 | AG79: 1775 | AH79: 1326 | AI79: 444

Sheet 2023_2ANO_LP_LTR + ECT
A1: Tipo | B1: Código país | C1: País | D1: Código estado | E1: Estado | F1: Código regional | G1: Regional | H1: Código município | I1: Município | J1: Código escola | K1: Escola | L1: Código turma | M1: Turma | N1: Documento | O1: Edição | P1: Rede | Q1: Etapa | R1: Disciplina | S1: CD_ENSINO | T1: DC_ENSINO | U1: Previsto | V1: Efetivo | W1: Participação % | X1: Proficiência | Y1: Desvio Padrão | Z1: Padrão de Desempenho | AA1: Acertos no Teste % | AB1: Abaixo do Básico % | AC1: Básico % | AD1: Proficiente % | AE1: Avançado % | AF1: Abaixo do Básico | AG1: Básico | AH1: Proficiente | AI1: Avançado
A2: MUNICIPIO | B2: 01058 | C2: Brasil | D2: 32 | E2: ESPÍRITO SANTO | F2: 000037 | G2: SRE AFONSO CLAUDIO | H2: 3200102 | I2: AFONSO CLAUDIO | J2: - | K2: - | L2: - | M2: - | N2: 3200102 | O2: 2023 | P2: Municipal | Q2: ENSINO FUNDAMENTAL DE 9 ANOS - 2º ANO | R2: Língua Portuguesa - Escrita e Leitura | S2: 9 | T2: ENSINO FUNDAMENTAL | U2: 314 | V2: 304 | W2: 96.815287 | X2: 733.33626 | Y2: 102.44143 | Z2: Avançado | AA2: 69,82553529 | AB2: 0.02631579 | AC2: 0.052631579 | AD2: 0.25 | AE2: 0.67105263 | AF2: 8 | AG2: 16 | AH2: 76 | AI2: 204 | AK2: ='2023_2ANO_LP_LTR + ECT'!$AB2/100 -> 0.0002631579 | AL2: ='2023_2ANO_LP_LTR + ECT'!$AC2/100 -> 0.00052631579 | AM2: ='2023_2ANO_LP_LTR + ECT'!$AD2/100 -> 0.0025 | AN2: ='2023_2ANO_LP_LTR + ECT'!$AE2/100 -> 0.0067105263 | AO2: =SUM(AK2:AN2) -> 0.01
A3: MUNICIPIO | B3: 01058 | C3: Brasil | D3: 32 | E3: ESPÍRITO SANTO | F3: 000037 | G3: SRE AFONSO CLAUDIO | H3: 3201159 | I3: BREJETUBA | J3: - | K3: - | L3: - | M3: - | N3: 3201159 | O3: 2023 | P3: Municipal | Q3: ENSINO FUNDAMENTAL DE 9 ANOS - 2º ANO | R3: Língua Portuguesa - Escrita e Leitura | S3: 9 | T3: ENSINO FUNDAMENTAL | U3: 153 | V3: 142 | W3: 92.810458 | X3: 641.26633 | Y3: 114.60415 | Z3: Proficiente | AA3: 59,09219858 | AB3: 0.13380282 | AC3: 0.15492958 | AD3: 0.38732394 | AE3: 0.32394366 | AF3: 19 | AG3: 22 | AH3: 55 | AI3: 46 | AK3: ='2023_2ANO_LP_LTR + ECT'!$AB3/100 -> 0.0013380282 | AL3: ='2023_2ANO_LP_LTR + ECT'!$AC3/100 -> 0.0015492958 | AM3: ='2023_2ANO_LP_LTR + ECT'!$AD3/100 -> 0.0038732394 | AN3: ='2023_2ANO_LP_LTR + ECT'!$AE3/100 -> 0.0032394366 | AO3: =SUM(AK3:AN3) -> 0.01
A4: MUNICIPIO | B4: 01058 | C4: Brasil | D4: 32 | E4: ESPÍRITO SANTO | F4: 000037 | G4: SRE AFONSO CLAUDIO | H4: 3201704 | I4: CONCEICAO DO CASTELO | J4: - | K4: - | L4: - | M4: - | N4: 3201704 | O4: 2023 | P4: Municipal | Q4: ENSINO FUNDAMENTAL DE 9 ANOS - 2º ANO | R4: Língua Portuguesa - Escrita e Leitura | S4: 9 | T4: ENSINO FUNDAMENTAL | U4: 172 | V4: 167 | W4: 97.093023 | X4: 685.58255 | Y4: 103.71384 | Z4: Proficiente | AA4: 63,63197295 | AB4: 0.083832335 | AC4: 0.071856287 | AD4: 0.34131737 | AE4: 0.50299401 | AF4: 14 | AG4: 12 | AH4: 57 | AI4: 84 | AK4: ='2023_2ANO_LP_LTR + ECT'!$AB4/100 -> 0.00083832335 | AL4: ='2023_2ANO_LP_LTR + ECT'!$AC4/100 -> 0.00071856287 | AM4: ='2023_2ANO_LP_LTR + ECT'!$AD4/100 -> 0.0034131737 | AN4: ='2023_2ANO_LP_LTR + ECT'!$AE4/100 -> 0.0050299401 | AO4: =SUM(AK4:AN4) -> 0.01
A5: MUNICIPIO | B5: 01058 | C5: Brasil | D5: 32 | E5: ESPÍRITO SANTO | F5: 000037 | G5: SRE AFONSO CLAUDIO | H5: 3201902 | I5: DOMINGOS MARTINS | J5: - | K5: - | L5: - | M5: - | N5: 3201902 | O5: 2023 | P5: Municipal | Q5: ENSINO FUNDAMENTAL DE 9 ANOS - 2º ANO | R5: Língua Portuguesa - Escrita e Leitura | S5: 9 | T5: ENSINO FUNDAMENTAL | U5: 457 | V5: 439 | W5: 96.061269 | X5: 704.30242 | Y5: 112.14237 | Z5: Avançado | AA5: 66,22425629 | AB5: 0.079726651 | AC5: 0.056947608 | AD5: 0.27562642 | AE5: 0.58769932 | AF5: 35 | AG5: 25 | AH5: 121 | AI5: 258 | AK5: ='2023_2ANO_LP_LTR + ECT'!$AB5/100 -> 0.00079726651 | AL5: ='2023_2ANO_LP_LTR + ECT'!$AC5/100 -> 0.00056947608 | AM5: ='2023_2ANO_LP_LTR + ECT'!$AD5/100 -> 0.0027562642 | AN5: ='2023_2ANO_LP_LTR + ECT'!$AE5/100 -> 0.0058769932 | AO5: =SUM(AK5:AN5) -> 0.01
A6: MUNICIPIO | B6: 01058 | C6: Brasil | D6: 32 | E6: ESPÍRITO SANTO | F6: 000037 | G6: SRE AFONSO CLAUDIO | H6: 3203163 | I6: LARANJA DA TERRA | J6: - | K6: - | L6: - | M6: - | N6: 3203163 | O6: 2023 | P6: Municipal | Q6: ENSINO FUNDAMENTAL DE 9 ANOS - 2º ANO | R6: Língua Portuguesa - Escrita e Leitura | S6: 9 | T6: ENSINO FUNDAMENTAL | U6: 114 | V6: 108 | W6: 94.736842 | X6: 712.87109 | Y6: 90.456575 | Z6: Avançado | AA6: 68,74074074 | AB6: 0.018518519 | AC6: 0.083333333 | AD6: 0.33333333 | AE6: 0.56481481 | AF6: 2 | AG6: 9 | AH6: 36 | AI6: 61 | AK6: ='2023_2ANO_LP_LTR + ECT'!$AB6/100 -> 0.00018518519 | AL6: ='2023_2ANO_LP_LTR + ECT'!$AC6/100 -> 0.00083333333 | AM6: ='2023_2ANO_LP_LTR + ECT'!$AD6/100 -> 0.0033333333 | AN6: ='2023_2ANO_LP_LTR + ECT'!$AE6/100 -> 0.0056481481 | AO6: =SUM(AK6:AN6) -> 0.01
A7: MUNICIPIO | B7: 01058 | C7: Brasil | D7: 32 | E7: ESPÍRITO SANTO | F7: 000037 | G7: SRE AFONSO CLAUDIO | H7: 3204559 | I7: SANTA MARIA DE JETIBA | J7: - | K7: - | L7: - | M7: - | N7: 3204559 | O7: 2023 | P7: Municipal | Q7: ENSINO FUNDAMENTAL DE 9 ANOS - 2º ANO | R7: Língua Portuguesa - Escrita e Leitura | S7: 9 | T7: ENSINO FUNDAMENTAL | U7: 328 | V7: 307 | W7: 93.597561 | X7: 707.17769 | Y7: 106.16824 | Z7: Avançado | AA7: 69,51633987 | AB7: 0.058631922 | AC7: 0.084690554 | AD7: 0.27035831 | AE7: 0.58631922 | AF7: 18 | AG7: 26 | AH7: 83 | AI7: 180 | AK7: ='2023_2ANO_LP_LTR + ECT'!$AB7/100 -> 0.00058631922 | AL7: ='2023_2ANO_LP_LTR + ECT'!$AC7/100 -> 0.00084690554 | AM7: ='2023_2ANO_LP_LTR + ECT'!$AD7/100 -> 0.0027035831 | AN7: ='2023_2ANO_LP_LTR + ECT'!$AE7/100 -> 0.0058631922 | AO7: =SUM(AK7:AN7) -> 0.01
A8: MUNICIPIO | B8: 01058 | C8: Brasil | D8: 32 | E8: ESPÍRITO SANTO | F8: 000037 | G8: SRE AFONSO CLAUDIO | H8: 3205069 | I8: VENDA NOVA DO IMIGRANTE | J8: - | K8: - | L8: - | M8: - | N8: 3205069 | O8: 2023 | P8: Municipal | Q8: ENSINO FUNDAMENTAL DE 9 ANOS - 2º ANO | R8: Língua Portuguesa - Escrita e Leitura | S8: 9 | T8: ENSINO FUNDAMENTAL | U8: 118 | V8: 104 | W8: 88.135593 | X8: 690.85151 | Y8: 93.583307 | Z8: Proficiente | AA8: 65,39360873 | AB8: 0.057692308 | AC8: 0.057692308 | AD8: 0.36538462 | AE8: 0.51923077 | AF8: 6 | AG8: 6 | AH8: 38 | AI8: 54 | AK8: ='2023_2ANO_LP_LTR + ECT'!$AB8/100 -> 0.00057692308 | AL8: ='2023_2ANO_LP_LTR + ECT'!$AC8/100 -> 0.00057692308 | AM8: ='2023_2ANO_LP_LTR + ECT'!$AD8/100 -> 0.0036538462 | AN8: ='2023_2ANO_LP_LTR + ECT'!$AE8/100 -> 0.0051923077 | AO8: =SUM(AK8:AN8) -> 0.01
A9: MUNICIPIO | B9: 01058 | C9: Brasil | D9: 32 | E9: ESPÍRITO SANTO | F9: 000032 | G9: SRE BARRA DE SAO FRANCISCO | H9: 3200169 | I9: AGUA DOCE DO NORTE | J9: - | K9: - | L9: - | M9: - | N9: 3200169 | O9: 2023 | P9: Municipal | Q9: ENSINO FUNDAMENTAL DE 9 ANOS - 2º ANO | R9: Língua Portuguesa - Escrita e Leitura | S9: 9 | T9: ENSINO FUNDAMENTAL | U9: 188 | V9: 170 | W9: 90.425532 | X9: 681.24178 | Y9: 111.26406 | Z9: Proficiente | AA9: 67,64705882 | AB9: 0.076470588 | AC9: 0.11176471 | AD9: 0.35882353 | AE9: 0.45294118 | AF9: 13 | AG9: 19 | AH9: 61 | AI9: 77 | AK9: ='2023_2ANO_LP_LTR + ECT'!$AB9/100 -> 0.00076470588 | AL9: ='2023_2ANO_LP_LTR + ECT'!$AC9/100 -> 0.0011176471 | AM9: ='2023_2ANO_LP_LTR + ECT'!$AD9/100 -> 0.0035882353 | AN9: ='2023_2ANO_LP_LTR + ECT'!$AE9/100 -> 0.0045294118 | AO9: =SUM(AK9:AN9) -> 0.01
A10: MUNICIPIO | B10: 01058 | C10: Brasil | D10: 32 | E10: ESPÍRITO SANTO | F10: 000032 | G10: SRE BARRA DE SAO FRANCISCO | H10: 3200136 | I10: AGUIA BRANCA | J10: - | K10: - | L10: - | M10: - | N10: 3200136 | O10: 2023 | P10: Municipal | Q10: ENSINO FUNDAMENTAL DE 9 ANOS - 2º ANO | R10: Língua Portuguesa - Escrita e Leitura | S10: 9 | T10: ENSINO FUNDAMENTAL | U10: 152 | V10: 143 | W10: 94.078947 | X10: 722.8002 | Y10: 76.887422 | Z10: Avançado | AA10: 72,05633803 | AB10: 0.006993007 | AC10: 0.041958042 | AD10: 0.34265734 | AE10: 0.60839161 | AF10: 1 | AG10: 6 | AH10: 49 | AI10: 87 | AK10: ='2023_2ANO_LP_LTR + ECT'!$AB10/100 -> 6.993007e-05 | AL10: ='2023_2ANO_LP_LTR + ECT'!$AC10/100 -> 0.00041958042 | AM10: ='2023_2ANO_LP_LTR + ECT'!$AD10/100 -> 0.0034265734 | AN10: ='2023_2ANO_LP_LTR + ECT'!$AE10/100 -> 0.0060839161 | AO10: =SUM(AK10:AN10) -> 0.01
A11: MUNICIPIO | B11: 01058 | C11: Brasil | D11: 32 | E11: ESPÍRITO SANTO | F11: 000032 | G11: SRE BARRA DE SAO FRANCISCO | H11: 3200904 | I11: BARRA DE SAO FRANCISCO | J11: - | K11: - | L11: - | M11: - | N11: 3200904 | O11: 2023 | P11: Municipal | Q11: ENSINO FUNDAMENTAL DE 9 ANOS - 2º ANO | R11: Língua Portuguesa - Escrita e Leitura | S11: 9 | T11: ENSINO FUNDAMENTAL | U11: 523 | V11: 489 | W11: 93.499044 | X11: 682.40324 | Y11: 99.451069 | Z11: Proficiente | AA11: 64,94650206 | AB11: 0.065439673 | AC11: 0.096114519 | AD11: 0.37627812 | AE11: 0.46216769 | AF11: 32 | AG11: 47 | AH11: 184 | AI11: 226 | AK11: ='2023_2ANO_LP_LTR + ECT'!$AB11/100 -> 0.00065439673 | AL11: ='2023_2ANO_LP_LTR + ECT'!$AC11/100 -> 0.00096114519 | AM11: ='2023_2ANO_LP_LTR + ECT'!$AD11/100 -> 0.0037627812 | AN11: ='2023_2ANO_LP_LTR + ECT'!$AE11/100 -> 0.0046216769 | AO11: =SUM(AK11:AN11) -> 0.01
A12: MUNICIPIO | B12: 01058 | C12: Brasil | D12: 32 | E12: ESPÍRITO SANTO | F12: 000032 | G12: SRE BARRA DE SAO FRANCISCO | H12: 3202108 | I12: ECOPORANGA | J12: - | K12: - | L12: - | M12: - | N12: 3202108 | O12: 2023 | P12: Municipal | Q12: ENSINO FUNDAMENTAL DE 9 ANOS - 2º ANO | R12: Língua Portuguesa - Escrita e Leitura | S12: 9 | T12: ENSINO FUNDAMENTAL | U12: 231 | V12: 215 | W12: 93.073593 | X12: 665.7616 | Y12: 114.04575 | Z12: Proficiente | AA12: 60,54856284 | AB12: 0.1255814 | AC12: 0.088372093 | AD12: 0.37209302 | AE12: 0.41395349 | AF12: 27 | AG12: 19 | AH12: 80 | AI12: 89 | AK12: ='2023_2ANO_LP_LTR + ECT'!$AB12/100 -> 0.001255814 | AL12: ='2023_2ANO_LP_LTR + ECT'!$AC12/100 -> 0.00088372093 | AM12: ='2023_2ANO_LP_LTR + ECT'!$AD12/100 -> 0.0037209302 | AN12: ='2023_2ANO_LP_LTR + ECT'!$AE12/100 -> 0.0041395349 | AO12: =SUM(AK12:AN12) -> 0.01
A13: MUNICIPIO | B13: 01058 | C13: Brasil | D13: 32 | E13: ESPÍRITO SANTO | F13: 000032 | G13: SRE BARRA DE SAO FRANCISCO | H13: 3203304 | I13: MANTENOPOLIS | J13: - | K13: - | L13: - | M13: - | N13: 3203304 | O13: 2023 | P13: Municipal | Q13: ENSINO FUNDAMENTAL DE 9 ANOS - 2º ANO | R13: Língua Portuguesa - Escrita e Leitura | S13: 9 | T13: ENSINO FUNDAMENTAL | U13: 164 | V13: 155 | W13: 94.512195 | X13: 747.56526 | Y13: 95.25604 | Z13: Avançado | AA13: 76,03542589 | AB13: 0.012903226 | AC13: 0.038709677 | AD13: 0.21935484 | AE13: 0.72903226 | AF13: 2 | AG13: 6 | AH13: 34 | AI13: 113 | AK13: ='2023_2ANO_LP_LTR + ECT'!$AB13/100 -> 0.00012903226 | AL13: ='2023_2ANO_LP_LTR + ECT'!$AC13/100 -> 0.00038709677 | AM13: ='2023_2ANO_LP_LTR + ECT'!$AD13/100 -> 0.0021935484 | AN13: ='2023_2ANO_LP_LTR + ECT'!$AE13/100 -> 0.0072903226 | AO13: =SUM(AK13:AN13) -> 0.01
... A20: MUNICIPIO | B20: 01058 | C20: Brasil | D20: 32 | E20: ESPÍRITO SANTO | F20: 000035 | G20: SRE CACHOEIRO DE ITAPEMIRIM | H20: 3203320 | I20: MARATAIZES | J20: - | K20: - | L20: - | M20: - | N20: 3203320 | O20: 2023 | P20: Municipal | Q20: ENSINO FUNDAMENTAL DE 9 ANOS - 2º ANO | R20: Língua Portuguesa - Escrita e Leitura | S20: 9 | T20: ENSINO FUNDAMENTAL | U20: 682 | V20: 612 | W20: 89.73607 | X20: 666.5482 | Y20: 101.39403 | Z20: Proficiente | AA20: 61,17374005 | AB20: 0.08496732 | AC20: 0.10457516 | AD20: 0.42156863 | AE20: 0.38888889 | AF20: 52 | AG20: 64 | AH20: 258 | AI20: 238 | AK20: ='2023_2ANO_LP_LTR + ECT'!$AB20/100 -> 0.0008496732 | AL20: ='2023_2ANO_LP_LTR + ECT'!$AC20/100 -> 0.0010457516 | AM20: ='2023_2ANO_LP_LTR + ECT'!$AD20/100 -> 0.0042156863 | AN20: ='2023_2ANO_LP_LTR + ECT'!$AE20/100 -> 0.0038888889 | AO20: =SUM(AK20:AN20) -> 0.01
A21: MUNICIPIO | B21: 01058 | C21: Brasil | D21: 32 | E21: ESPÍRITO SANTO | F21: 000035 | G21: SRE CACHOEIRO DE ITAPEMIRIM | H21: 3203403 | I21: MIMOSO DO SUL | J21: - | K21: - | L21: - | M21: - | N21: 3203403 | O21: 2023 | P21: Municipal | Q21: ENSINO FUNDAMENTAL DE 9 ANOS - 2º ANO | R21: Língua Portuguesa - Escrita e Leitura | S21: 9 | T21: ENSINO FUNDAMENTAL | U21: 313 | V21: 283 | W21: 90.415335 | X21: 670.84882 | Y21: 106.98598 | Z21: Proficiente | AA21: 63,91366906 | AB21: 0.088339223 | AC21: 0.13427562 | AD21: 0.35335689 | AE21: 0.41342756 | AF21: 25 | AG21: 38 | AH21: 100 | AI21: 117 | AK21: ='2023_2ANO_LP_LTR + ECT'!$AB21/100 -> 0.00088339223 | AL21: ='2023_2ANO_LP_LTR + ECT'!$AC21/100 -> 0.0013427562 | AM21: ='2023_2ANO_LP_LTR + ECT'!$AD21/100 -> 0.0035335689 | AN21: ='2023_2ANO_LP_LTR + ECT'!$AE21/100 -> 0.0041342756 | AO21: =SUM(AK21:AN21) -> 0.0098939929 | AP21: ='2023_2ANO_LP_LTR + ECT'!$AF21/SUM('2023_2ANO_LP_LTR + ECT'!$AF21:$AI21) -> 0.089285714
A22: MUNICIPIO | B22: 01058 | C22: Brasil | D22: 32 | E22: ESPÍRITO SANTO | F22: 000035 | G22: SRE CACHOEIRO DE ITAPEMIRIM | H22: 3203809 | I22: MUQUI | J22: - | K22: - | L22: - | M22: - | N22: 3203809 | O22: 2023 | P22: Municipal | Q22: ENSINO FUNDAMENTAL DE 9 ANOS - 2º ANO | R22: Língua Portuguesa - Escrita e Leitura | S22: 9 | T22: ENSINO FUNDAMENTAL | U22: 156 | V22: 152 | W22: 97.435897 | X22: 648.44273 | Y22: 107.48467 | Z22: Proficiente | AA22: 60,13245033 | AB22: 0.10526316 | AC22: 0.19736842 | AD22: 0.33552632 | AE22: 0.36184211 | AF22: 16 | AG22: 30 | AH22: 51 | AI22: 55 | AK22: ='2023_2ANO_LP_LTR + ECT'!$AB22/100 -> 0.0010526316 | AL22: ='2023_2ANO_LP_LTR + ECT'!$AC22/100 -> 0.0019736842 | AM22: ='2023_2ANO_LP_LTR + ECT'!$AD22/100 -> 0.0033552632 | AN22: ='2023_2ANO_LP_LTR + ECT'!$AE22/100 -> 0.0036184211 | AO22: =SUM(AK22:AN22) -> 0.01
A23: MUNICIPIO | B23: 01058 | C23: Brasil | D23: 32 | E23: ESPÍRITO SANTO | F23: 000035 | G23: SRE CACHOEIRO DE ITAPEMIRIM | H23: 3204302 | I23: PRESIDENTE KENNEDY | J23: - | K23: - | L23: - | M23: - | N23: 3204302 | O23: 2023 | P23: Municipal | Q23: ENSINO FUNDAMENTAL DE 9 ANOS - 2º ANO | R23: Língua Portuguesa - Escrita e Leitura | S23: 9 | T23: ENSINO FUNDAMENTAL | U23: 228 | V23: 211 | W23: 92.54386 | X23: 648.70183 | Y23: 110.41262 | Z23: Proficiente | AA23: 62,14462889 | AB23: 0.09478673 | AC23: 0.17535545 | AD23: 0.40758294 | AE23: 0.32227488 | AF23: 20 | AG23: 37 | AH23: 86 | AI23: 68 | AK23: ='2023_2ANO_LP_LTR + ECT'!$AB23/100 -> 0.0009478673 | AL23: ='2023_2ANO_LP_LTR + ECT'!$AC23/100 -> 0.0017535545 | AM23: ='2023_2ANO_LP_LTR + ECT'!$AD23/100 -> 0.0040758294 | AN23: ='2023_2ANO_LP_LTR + ECT'!$AE23/100 -> 0.0032227488 | AO23: =SUM(AK23:AN23) -> 0.01
A24: MUNICIPIO | B24: 01058 | C24: Brasil | D24: 32 | E24: ESPÍRITO SANTO | F24: 000035 | G24: SRE CACHOEIRO DE ITAPEMIRIM | H24: 3204401 | I24: RIO NOVO DO SUL | J24: - | K24: - | L24: - | M24: - | N24: 3204401 | O24: 2023 | P24: Municipal | Q24: ENSINO FUNDAMENTAL DE 9 ANOS - 2º ANO | R24: Língua Portuguesa - Escrita e Leitura | S24: 9 | T24: ENSINO FUNDAMENTAL | U24: 145 | V24: 133 | W24: 91.724138 | X24: 700.08429 | Y24: 109.70424 | Z24: Proficiente | AA24: 68,64227396 | AB24: 0.067669173 | AC24: 0.052631579 | AD24: 0.32330827 | AE24: 0.55639098 | AF24: 9 | AG24: 7 | AH24: 43 | AI24: 74 | AK24: ='2023_2ANO_LP_LTR + ECT'!$AB24/100 -> 0.00067669173 | AL24: ='2023_2ANO_LP_LTR + ECT'!$AC24/100 -> 0.00052631579 | AM24: ='2023_2ANO_LP_LTR + ECT'!$AD24/100 -> 0.0032330827 | AN24: ='2023_2ANO_LP_LTR + ECT'!$AE24/100 -> 0.0055639098 | AO24: =SUM(AK24:AN24) -> 0.01
A25: MUNICIPIO | B25: 01058 | C25: Brasil | D25: 32 | E25: ESPÍRITO SANTO | F25: 000035 | G25: SRE CACHOEIRO DE ITAPEMIRIM | H25: 3205036 | I25: VARGEM ALTA | J25: - | K25: - | L25: - | M25: - | N25: 3205036 | O25: 2023 | P25: Municipal | Q25: ENSINO FUNDAMENTAL DE 9 ANOS - 2º ANO | R25: Língua Portuguesa - Escrita e Leitura | S25: 9 | T25: ENSINO FUNDAMENTAL | U25: 305 | V25: 274 | W25: 89.836066 | X25: 662.07547 | Y25: 113.07488 | Z25: Proficiente | AA25: 59,59507042 | AB25: 0.10218978 | AC25: 0.1350365 | AD25: 0.37956204 | AE25: 0.38321168 | AF25: 28 | AG25: 37 | AH25: 104 | AI25: 105 | AK25: ='2023_2ANO_LP_LTR + ECT'!$AB25/100 -> 0.0010218978 | AL25: ='2023_2ANO_LP_LTR + ECT'!$AC25/100 -> 0.001350365 | AM25: ='2023_2ANO_LP_LTR + ECT'!$AD25/100 -> 0.0037956204 | AN25: ='2023_2ANO_LP_LTR + ECT'!$AE25/100 -> 0.0038321168 | AO25: =SUM(AK25:AN25) -> 0.01
A26: MUNICIPIO | B26: 01058 | C26: Brasil | D26: 32 | E26: ESPÍRITO SANTO | F26: 000027 | G26: SRE CARAPINA | H26: 3202207 | I26: FUNDAO | J26: - | K26: - | L26: - | M26: - | N26: 3202207 | O26: 2023 | P26: Municipal | Q26: ENSINO FUNDAMENTAL DE 9 ANOS - 2º ANO | R26: Língua Portuguesa - Escrita e Leitura | S26: 9 | T26: ENSINO FUNDAMENTAL | U26: 256 | V26: 222 | W26: 86.71875 | X26: 637.99642 | Y26: 116.5006 | Z26: Proficiente | AA26: 57,26292710 | AB26: 0.13963964 | AC26: 0.17117117 | AD26: 0.38738739 | AE26: 0.3018018 | AF26: 31 | AG26: 38 | AH26: 86 | AI26: 67 | AK26: ='2023_2ANO_LP_LTR + ECT'!$AB26/100 -> 0.0013963964 | AL26: ='2023_2ANO_LP_LTR + ECT'!$AC26/100 -> 0.0017117117 | AM26: ='2023_2ANO_LP_LTR + ECT'!$AD26/100 -> 0.0038738739 | AN26: ='2023_2ANO_LP_LTR + ECT'!$AE26/100 -> 0.003018018 | AO26: =SUM(AK26:AN26) -> 0.01
A27: MUNICIPIO | B27: 01058 | C27: Brasil | D27: 32 | E27: ESPÍRITO SANTO | F27: 000027 | G27: SRE CARAPINA | H27: 3204609 | I27: SANTA TERESA | J27: - | K27: - | L27: - | M27: - | N27: 3204609 | O27: 2023 | P27: Municipal | Q27: ENSINO FUNDAMENTAL DE 9 ANOS - 2º ANO | R27: Língua Portuguesa - Escrita e Leitura | S27: 9 | T27: ENSINO FUNDAMENTAL | U27: 215 | V27: 185 | W27: 86.046512 | X27: 704.1673 | Y27: 102.67111 | Z27: Avançado | AA27: 66,24783362 | AB27: 0.048648649 | AC27: 0.064864865 | AD27: 0.33513514 | AE27: 0.55135135 | AF27: 9 | AG27: 12 | AH27: 62 | AI27: 102 | AK27: ='2023_2ANO_LP_LTR + ECT'!$AB27/100 -> 0.00048648649 | AL27: ='2023_2ANO_LP_LTR + ECT'!$AC27/100 -> 0.00064864865 | AM27: ='2023_2ANO_LP_LTR + ECT'!$AD27/100 -> 0.0033513514 | AN27: ='2023_2ANO_LP_LTR + ECT'!$AE27/100 -> 0.0055135135 | AO27: =SUM(AK27:AN27) -> 0.01
A28: MUNICIPIO | B28: 01058 | C28: Brasil | D28: 32 | E28: ESPÍRITO SANTO | F28: 000027 | G28: SRE CARAPINA | H28: 3205002 | I28: SERRA | J28: - | K28: - | L28: - | M28: - | N28: 3205002 | O28: 2023 | P28: Municipal | Q28: ENSINO FUNDAMENTAL DE 9 ANOS - 2º ANO | R28: Língua Portuguesa - Escrita e Leitura | S28: 9 | T28: ENSINO FUNDAMENTAL | U28: 6645 | V28: 5731 | W28: 86.245297 | X28: 633.07706 | Y28: 109.10413 | Z28: Proficiente | AA28: 54,88332260 | AB28: 0.14238353 | AC28: 0.18112022 | AD28: 0.39626592 | AE28: 0.28023033 | AF28: 816 | AG28: 1038 | AH28: 2271 | AI28: 1606 | AK28: ='2023_2ANO_LP_LTR + ECT'!$AB28/100 -> 0.0014238353 | AL28: ='2023_2ANO_LP_LTR + ECT'!$AC28/100 -> 0.0018112022 | AM28: ='2023_2ANO_LP_LTR + ECT'!$AD28/100 -> 0.0039626592 | AN28: ='2023_2ANO_LP_LTR + ECT'!$AE28/100 -> 0.0028023033 | AO28: =SUM(AK28:AN28) -> 0.01
A29: MUNICIPIO | B29: 01058 | C29: Brasil | D29: 32 | E29: ESPÍRITO SANTO | F29: 000027 | G29: SRE CARAPINA | H29: 3205309 | I29: VITORIA | J29: - | K29: - | L29: - | M29: - | N29: 3205309 | O29: 2023 | P29: Municipal | Q29: ENSINO FUNDAMENTAL DE 9 ANOS - 2º ANO | R29: Língua Portuguesa - Escrita e Leitura | S29: 9 | T29: ENSINO FUNDAMENTAL | U29: 3090 | V29: 2829 | W29: 91.553398 | X29: 652.26692 | Y29: 103.36162 | Z29: Proficiente | AA29: 60,14199218 | AB29: 0.10109579 | AC29: 0.15800636 | AD29: 0.39483917 | AE29: 0.34464475 | AF29: 286 | AG29: 447 | AH29: 1117 | AI29: 975 | AK29: ='2023_2ANO_LP_LTR + ECT'!$AB29/100 -> 0.0010109579 | AL29: ='2023_2ANO_LP_LTR + ECT'!$AC29/100 -> 0.0015800636 | AM29: ='2023_2ANO_LP_LTR + ECT'!$AD29/100 -> 0.0039483917 | AN29: ='2023_2ANO_LP_LTR + ECT'!$AE29/100 -> 0.0034464475 | AO29: =SUM(AK29:AN29) -> 0.0099858607 | AP29: ='2023_2ANO_LP_LTR + ECT'!$AF29/SUM('2023_2ANO_LP_LTR + ECT'!$AF29:$AI29) -> 0.10123894
A30: MUNICIPIO | B30: 01058 | C30: Brasil | D30: 32 | E30: ESPÍRITO SANTO | F30: 000029 | G30: SRE CARIACICA | H30: 3201308 | I30: CARIACICA | J30: - | K30: - | L30: - | M30: - | N30: 3201308 | O30: 2023 | P30: Municipal | Q30: ENSINO FUNDAMENTAL DE 9 ANOS - 2º ANO | R30: Língua Portuguesa - Escrita e Leitura | S30: 9 | T30: ENSINO FUNDAMENTAL | U30: 5298 | V30: 4640 | W30: 87.580219 | X30: 633.17489 | Y30: 112.597 | Z30: Proficiente | AA30: 57,01880826 | AB30: 0.15280172 | AC30: 0.19073276 | AD30: 0.35538793 | AE30: 0.30107759 | AF30: 709 | AG30: 885 | AH30: 1649 | AI30: 1397 | AK30: ='2023_2ANO_LP_LTR + ECT'!$AB30/100 -> 0.0015280172 | AL30: ='2023_2ANO_LP_LTR + ECT'!$AC30/100 -> 0.0019073276 | AM30: ='2023_2ANO_LP_LTR + ECT'!$AD30/100 -> 0.0035538793 | AN30: ='2023_2ANO_LP_LTR + ECT'!$AE30/100 -> 0.0030107759 | AO30: =SUM(AK30:AN30) -> 0.01
A31: MUNICIPIO | B31: 01058 | C31: Brasil | D31: 32 | E31: ESPÍRITO SANTO | F31: 000029 | G31: SRE CARIACICA | H31: 3203346 | I31: MARECHAL FLORIANO | J31: - | K31: - | L31: - | M31: - | N31: 3203346 | O31: 2023 | P31: Municipal | Q31: ENSINO FUNDAMENTAL DE 9 ANOS - 2º ANO | R31: Língua Portuguesa - Escrita e Leitura | S31: 9 | T31: ENSINO FUNDAMENTAL | U31: 282 | V31: 255 | W31: 90.425532 | X31: 685.91818 | Y31: 97.883616 | Z31: Proficiente | AA31: 61,84251969 | AB31: 0.050980392 | AC31: 0.074509804 | AD31: 0.40784314 | AE31: 0.46666667 | AF31: 13 | AG31: 19 | AH31: 104 | AI31: 119 | AK31: ='2023_2ANO_LP_LTR + ECT'!$AB31/100 -> 0.00050980392 | AL31: ='2023_2ANO_LP_LTR + ECT'!$AC31/100 -> 0.00074509804 | AM31: ='2023_2ANO_LP_LTR + ECT'!$AD31/100 -> 0.0040784314 | AN31: ='2023_2ANO_LP_LTR + ECT'!$AE31/100 -> 0.0046666667 | AO31: =SUM(AK31:AN31) -> 0.01
A32: MUNICIPIO | B32: 01058 | C32: Brasil | D32: 32 | E32: ESPÍRITO SANTO | F32: 000029 | G32: SRE CARIACICA | H32: 3204500 | I32: SANTA LEOPOLDINA | J32: - | K32: - | L32: - | M32: - | N32: 3204500 | O32: 2023 | P32: Municipal | Q32: ENSINO FUNDAMENTAL DE 9 ANOS - 2º ANO | R32: Língua Portuguesa - Escrita e Leitura | S32: 9 | T32: ENSINO FUNDAMENTAL | U32: 169 | V32: 158 | W32: 93.491124 | X32: 700.39673 | Y32: 118.48697 | Z32: Proficiente | AA32: 67,84888204 | AB32: 0.088607595 | AC32: 0.056962025 | AD32: 0.28481013 | AE32: 0.56962025 | AF32: 14 | AG32: 9 | AH32: 45 | AI32: 90 | AK32: ='2023_2ANO_LP_LTR + ECT'!$AB32/100 -> 0.00088607595 | AL32: ='2023_2ANO_LP_LTR + ECT'!$AC32/100 -> 0.00056962025 | AM32: ='2023_2ANO_LP_LTR + ECT'!$AD32/100 -> 0.0028481013 | AN32: ='2023_2ANO_LP_LTR + ECT'!$AE32/100 -> 0.0056962025 | AO32: =SUM(AK32:AN32) -> 0.01
A33: MUNICIPIO | B33: 01058 | C33: Brasil | D33: 32 | E33: ESPÍRITO SANTO | F33: 000029 | G33: SRE CARIACICA | H33: 3205101 | I33: VIANA | J33: - | K33: - | L33: - | M33: - | N33: 3205101 | O33: 2023 | P33: Municipal | Q33: ENSINO FUNDAMENTAL DE 9 ANOS - 2º ANO | R33: Língua Portuguesa - Escrita e Leitura | S33: 9 | T33: ENSINO FUNDAMENTAL | U33: 1267 | V33: 1146 | W33: 90.449882 | X33: 670.62029 | Y33: 109.24176 | Z33: Proficiente | AA33: 63,59395279 | AB33: 0.10122164 | AC33: 0.13438045 | AD33: 0.32286213 | AE33: 0.44153578 | AF33: 116 | AG33: 154 | AH33: 370 | AI33: 506 | AK33: ='2023_2ANO_LP_LTR + ECT'!$AB33/100 -> 0.0010122164 | AL33: ='2023_2ANO_LP_LTR + ECT'!$AC33/100 -> 0.0013438045 | AM33: ='2023_2ANO_LP_LTR + ECT'!$AD33/100 -> 0.0032286213 | AN33: ='2023_2ANO_LP_LTR + ECT'!$AE33/100 -> 0.0044153578 | AO33: =SUM(AK33:AN33) -> 0.01
A34: MUNICIPIO | B34: 01058 | C34: Brasil | D34: 32 | E34: ESPÍRITO SANTO | F34: 000034 | G34: SRE COLATINA | H34: 3200359 | I34: ALTO RIO NOVO | J34: - | K34: - | L34: - | M34: - | N34: 3200359 | O34: 2023 | P34: Municipal | Q34: ENSINO FUNDAMENTAL DE 9 ANOS - 2º ANO | R34: Língua Portuguesa - Escrita e Leitura | S34: 9 | T34: ENSINO FUNDAMENTAL | U34: 115 | V34: 107 | W34: 93.043478 | X34: 649.14175 | Y34: 120.8885 | Z34: Proficiente | AA34: 65,34579439 | AB34: 0.1588785 | AC34: 0.14018692 | AD34: 0.28037383 | AE34: 0.42056075 | AF34: 17 | AG34: 15 | AH34: 30 | AI34: 45 | AK34: ='2023_2ANO_LP_LTR + ECT'!$AB34/100 -> 0.001588785 | AL34: ='2023_2ANO_LP_LTR + ECT'!$AC34/100 -> 0.0014018692 | AM34: ='2023_2ANO_LP_LTR + ECT'!$AD34/100 -> 0.0028037383 | AN34: ='2023_2ANO_LP_LTR + ECT'!$AE34/100 -> 0.0042056075 | AO34: =SUM(AK34:AN34) -> 0.01
A35: MUNICIPIO | B35: 01058 | C35: Brasil | D35: 32 | E35: ESPÍRITO SANTO | F35: 000034 | G35: SRE COLATINA | H35: 3200805 | I35: BAIXO GUANDU | J35: - | K35: - | L35: - | M35: - | N35: 3200805 | O35: 2023 | P35: Municipal | Q35: ENSINO FUNDAMENTAL DE 9 ANOS - 2º ANO | R35: Língua Portuguesa - Escrita e Leitura | S35: 9 | T35: ENSINO FUNDAMENTAL | U35: 376 | V35: 328 | W35: 87.234043 | X35: 659.98338 | Y35: 103.24338 | Z35: Proficiente | AA35: 63,17106745 | AB35: 0.11585366 | AC35: 0.13719512 | AD35: 0.34756098 | AE35: 0.39939024 | AF35: 38 | AG35: 45 | AH35: 114 | AI35: 131 | AK35: ='2023_2ANO_LP_LTR + ECT'!$AB35/100 -> 0.0011585366 | AL35: ='2023_2ANO_LP_LTR + ECT'!$AC35/100 -> 0.0013719512 | AM35: ='2023_2ANO_LP_LTR + ECT'!$AD35/100 -> 0.0034756098 | AN35: ='2023_2ANO_LP_LTR + ECT'!$AE35/100 -> 0.0039939024 | AO35: =SUM(AK35:AN35) -> 0.01
A36: MUNICIPIO | B36: 01058 | C36: Brasil | D36: 32 | E36: ESPÍRITO SANTO | F36: 000034 | G36: SRE COLATINA | H36: 3201506 | I36: COLATINA | J36: - | K36: - | L36: - | M36: - | N36: 3201506 | O36: 2023 | P36: Municipal | Q36: ENSINO FUNDAMENTAL DE 9 ANOS - 2º ANO | R36: Língua Portuguesa - Escrita e Leitura | S36: 9 | T36: ENSINO FUNDAMENTAL | U36: 1378 | V36: 1199 | W36: 87.01016 | X36: 675.54745 | Y36: 113.42734 | Z36: Proficiente | AA36: 61,20481118 | AB36: 0.10341952 | AC36: 0.10675563 | AD36: 0.32193495 | AE36: 0.46788991 | AF36: 124 | AG36: 128 | AH36: 386 | AI36: 561 | AK36: ='2023_2ANO_LP_LTR + ECT'!$AB36/100 -> 0.0010341952 | AL36: ='2023_2ANO_LP_LTR + ECT'!$AC36/100 -> 0.0010675563 | AM36: ='2023_2ANO_LP_LTR + ECT'!$AD36/100 -> 0.0032193495 | AN36: ='2023_2ANO_LP_LTR + ECT'!$AE36/100 -> 0.0046788991 | AO36: =SUM(AK36:AN36) -> 0.01
A37: MUNICIPIO | B37: 01058 | C37: Brasil | D37: 32 | E37: ESPÍRITO SANTO | F37: 000034 | G37: SRE COLATINA | H37: 3202256 | I37: GOVERNADOR LINDENBERG | J37: - | K37: - | L37: - | M37: - | N37: 3202256 | O37: 2023 | P37: Municipal | Q37: ENSINO FUNDAMENTAL DE 9 ANOS - 2º ANO | R37: Língua Portuguesa - Escrita e Leitura | S37: 9 | T37: ENSINO FUNDAMENTAL | U37: 90 | V37: 82 | W37: 91.111111 | X37: 624.37225 | Y37: 119.59435 | Z37: Proficiente | AA37: 60,20000000 | AB37: 0.19512195 | AC37: 0.15853659 | AD37: 0.42682927 | AE37: 0.2195122 | AF37: 16 | AG37: 13 | AH37: 35 | AI37: 18 | AK37: ='2023_2ANO_LP_LTR + ECT'!$AB37/100 -> 0.0019512195 | AL37: ='2023_2ANO_LP_LTR + ECT'!$AC37/100 -> 0.0015853659 | AM37: ='2023_2ANO_LP_LTR + ECT'!$AD37/100 -> 0.0042682927 | AN37: ='2023_2ANO_LP_LTR + ECT'!$AE37/100 -> 0.002195122 | AO37: =SUM(AK37:AN37) -> 0.01
A38: MUNICIPIO | B38: 01058 | C38: Brasil | D38: 32 | E38: ESPÍRITO SANTO | F38: 000034 | G38: SRE COLATINA | H38: 3202702 | I38: ITAGUACU | J38: - | K38: - | L38: - | M38: - | N38: 3202702 | O38: 2023 | P38: Municipal | Q38: ENSINO FUNDAMENTAL DE 9 ANOS - 2º ANO | R38: Língua Portuguesa - Escrita e Leitura | S38: 9 | T38: ENSINO FUNDAMENTAL | U38: 139 | V38: 128 | W38: 92.086331 | X38: 668.49994 | Y38: 117.89931 | Z38: Proficiente | AA38: 59,50726469 | AB38: 0.1015625 | AC38: 0.140625 | AD38: 0.3203125 | AE38: 0.4375 | AF38: 13 | AG38: 18 | AH38: 41 | AI38: 56 | AK38: ='2023_2ANO_LP_LTR + ECT'!$AB38/100 -> 0.001015625 | AL38: ='2023_2ANO_LP_LTR + ECT'!$AC38/100 -> 0.00140625 | AM38: ='2023_2ANO_LP_LTR + ECT'!$AD38/100 -> 0.003203125 | AN38: ='2023_2ANO_LP_LTR + ECT'!$AE38/100 -> 0.004375 | AO38: =SUM(AK38:AN38) -> 0.01
A39: MUNICIPIO | B39: 01058 | C39: Brasil | D39: 32 | E39: ESPÍRITO SANTO | F39: 000034 | G39: SRE COLATINA | H39: 3202900 | I39: ITARANA | J39: - | K39: - | L39: - | M39: - | N39: 3202900 | O39: 2023 | P39: Municipal | Q39: ENSINO FUNDAMENTAL DE 9 ANOS - 2º ANO | R39: Língua Portuguesa - Escrita e Leitura | S39: 9 | T39: ENSINO FUNDAMENTAL | U39: 107 | V39: 100 | W39: 93.457944 | X39: 687.70148 | Y39: 108.05316 | Z39: Proficiente | AA39: 61,93814433 | AB39: 0.07 | AC39: 0.08 | AD39: 0.4 | AE39: 0.45 | AF39: 7 | AG39: 8 | AH39: 40 | AI39: 45 | AK39: ='2023_2ANO_LP_LTR + ECT'!$AB39/100 -> 0.0007 | AL39: ='2023_2ANO_LP_LTR + ECT'!$AC39/100 -> 0.0008 | AM39: ='2023_2ANO_LP_LTR + ECT'!$AD39/100 -> 0.004 | AN39: ='2023_2ANO_LP_LTR + ECT'!$AE39/100 -> 0.0045 | AO39: =SUM(AK39:AN39) -> 0.01
A40: MUNICIPIO | B40: 01058 | C40: Brasil | D40: 32 | E40: ESPÍRITO SANTO | F40: 000034 | G40: SRE COLATINA | H40: 3203353 | I40: MARILANDIA | J40: - | K40: - | L40: - | M40: - | N40: 3203353 | O40: 2023 | P40: Municipal | Q40: ENSINO FUNDAMENTAL DE 9 ANOS - 2º ANO | R40: Língua Portuguesa - Escrita e Leitura | S40: 9 | T40: ENSINO FUNDAMENTAL | U40: 186 | V40: 173 | W40: 93.010753 | X40: 681.2444 | Y40: 112.73465 | Z40: Proficiente | AA40: 64,40000000 | AB40: 0.086705202 | AC40: 0.13294798 | AD40: 0.2716763 | AE40: 0.50867052 | AF40: 15 | AG40: 23 | AH40: 47 | AI40: 88 | AK40: ='2023_2ANO_LP_LTR + ECT'!$AB40/100 -> 0.00086705202 | AL40: ='2023_2ANO_LP_LTR + ECT'!$AC40/100 -> 0.0013294798 | AM40: ='2023_2ANO_LP_LTR + ECT'!$AD40/100 -> 0.002716763 | AN40: ='2023_2ANO_LP_LTR + ECT'!$AE40/100 -> 0.0050867052 | AO40: =SUM(AK40:AN40) -> 0.01
